Workbook

Sheet 项目汇总表
B1: 表一：基础信息表
A2: 共享系统部门名称 | B2: 项目名称 | C2: 主合同信息 | U2: 分包合同信息 | AH2: 间接费用 | AI2: 财务费用 | AJ2: 税金及附加 | AK2: 预交增值税 | AL2: 管理费比例 | AM2: 合同签订单位 | AN2: 项目管理单位 | AO2: 合同开工日期 | AP2: 预计竣工时间 | AQ2: 合同工期 | AR2: 工程类型 | AS2: 项目所在地（*省*市） | AT2: 项目状态 | AU2: 预计新增业主验工计价 | AV2: 预计新增分包验工计价 | AW2: 预计新增施工成本 | AX2: 预计新增施工收入 | AY2: 预计新增收款 | AZ2: 预计新增付款 | BA2: 预计新增两金 | BB2: 预计新增应付账款 | BC2: 1122应收账款 | BD2: 1123预付款项 | BE2: 1221其他应收款 | BF2: 1221-04-03其他应收款-民工工资保证金 | BG2: 1221-05其他应收款-预付款项转入 | BH2: 1221-09其他应收款-应收押金 | BI2: 1221-11其他应收款-应收押金 | BJ2: 1221-99其他应收款-其他 | BK2: 1231坏账准备 | BL2: 1484合同资产减值准备 | BM2: 1483合同资产 | BN2: 1531长期应收款 | BO2: 2202应付账款 | BP2: 2202-12应付账款-预付账款增值税 | BQ2: 2204合同负债 | BR2: 2204-10合同负债-预收账款增值税 | BS2: 2221-06应交税费-待转销项税额 | BT2: 2241其他应付款 | BU2: 2241-01其他应付款-保证金 | BV2: 2241-05其他应付款-应付押金 | BW2: 2241-99其他应付款-其他 | BX2: 2701长期应付款 | BY2: 2701-05长期应付款-应付质量保证金 | BZ2: 2701-99长期应付款-其他 | CA2: 5601-01-01-01合同履约成本-工程施工-合同成本-直接人工费（期末数） | CB2: 5601-01-01-02合同履约成本-工程施工-合同成本-直接材料费（期末数） | CC2: 5601-01-01-04合同履约成本-工程施工-合同成本-劳务成本（期末数） | CD2: 5601-01-01-05合同履约成本-工程施工-合同成本-专业分包成本（期末数） | CE2: 5601-01-01-06合同履约成本-工程施工-合同成本-其他直接费用（期末数） | CF2: 5601-01-01-07合同履约成本-工程施工-合同成本-间接费用转入（期末数） | CG2: 5601-01-01-01合同履约成本-工程施工-合同成本-直接人工费（当年借方发生数） | CH2: 5601-01-01-02合同履约成本-工程施工-合同成本-直接材料费（当年借方发生数） | CI2: 5601-01-01-04合同履约成本-工程施工-合同成本-劳务成本（当年借方发生数） | CJ2: 5601-01-01-05合同履约成本-工程施工-合同成本-专业分包成本（当年借方发生数） | CK2: 5601-01-01-06合同履约成本-工程施工-合同成本-其他直接费用（当年借方发生数） | CL2: 5601-01-01-07合同履约成本-工程施工-合同成本-间接费用转入（当年借方发生数） | CM2: 5601-02合同履约成本-劳务成本（当年借方发生数） | CN2: 5801-01合同结算-收入结转 | CO2: 5801-02合同结算-价款结算 | CP2: 6001主营业务收入（当年贷方发生数） | CQ2: 6401主营业务成本（当年借方发生数） | CR2: 应为零 | CS2: 应为零 | CT2: 应为零 | CU2: 应为零 | CV2: 应为零（正数为未验完，负数为超验） | CW2: 应为零 | CX2: 应尽量小，超过1000万预警 | CY2: 应尽量小 | CZ2: 校验不平的备注原因 | DA2: 计划完成的工作 | DB2: 完成情况
C3: 勘察设计合同额 | D3: 工程施工合同额 | E3: 设备采购合同额 | F3: 业主承担管理费合同额 | G3: 技术服务等合同额 | H3: 合同额合计 | I3: 合同额不含税合计 | J3: 工程施工预计总收入 | K3: 工程施工预计总成本 | L3: 累计验工计价 | M3: 累计验工计价税额 | N3: 工程施工验工计价 | O3: 累计确认收入 | P3: 工程施工确认收入 | Q3: 累计开票 | R3: 累计施工开票 | S3: 累计开票税金 | T3: 累计收款 | U3: 勘察设计合同额 | V3: 工程施工合同额 | W3: 设备采购合同额 | X3: 技术服务等合同额 | Y3: 合计 | Z3: 不含税合计 | AA3: 累计验工计价 | AB3: 施工验工计价 | AC3: 累计确认成本 | AD3: 施工确认成本 | AE3: 累计开票 | AF3: 累计施工开票 | AG3: 累计付款 | CR3: 业主往来检验 | CS3: 业主发票检验 | CT3: 业主收入检验 | CU3: 分包往来检验 | CV3: 分包施工验工计价校验 | CW3: 预缴税金检验 | CX3: 两金指标 | CY3: 验工进度校验
A4: ='武隆污水（不上系统）'!L4 -> 中铁二院武隆污水厂项目部 | B4: ='武隆污水（不上系统）'!M4 -> 武隆污水处理厂二期扩建工程EPC | C4: ='武隆污水（不上系统）'!E4 -> 2933770.4 | D4: ='武隆污水（不上系统）'!F4 -> 1.16656e+08 | E4: ='武隆污水（不上系统）'!G4 -> 0 | F4: ='武隆污水（不上系统）'!H4 -> 0 | G4: ='武隆污水（不上系统）'!I4 -> 0 | H4: =SUM(C4:G4) -> 1.1958977e+08 | I4: =C4/1.06+D4/1.09+E4/1.13+F4/1.06+G4/1.06 -> 1.0979156e+08 | J4: ='武隆污水（不上系统）'!V11 -> 1.0622063e+08 | K4: ='武隆污水（不上系统）'!W11 -> 1.0324322e+08 | L4: ='武隆污水（不上系统）'!G11 -> 1.1958977e+08 | M4: ='武隆污水（不上系统）'!H17 -> 10601433 | N4: ='武隆污水（不上系统）'!C11 -> 1.16656e+08 | O4: ='武隆污水（不上系统）'!S11 -> 1.0898834e+08 | P4: ='武隆污水（不上系统）'!O11 -> 1.0622063e+08 | Q4: ='武隆污水（不上系统）'!M11 -> 1.1958977e+08 | R4: ='武隆污水（不上系统）'!I11 -> 1.16656e+08 | S4: ='武隆污水（不上系统）'!X17 -> 10601433 | T4: ='武隆污水（不上系统）'!T11 -> 1.1958977e+08 | U4: ='武隆污水（不上系统）'!E5+'武隆污水（不上系统）'!E6 -> 2000000 | V4: ='武隆污水（不上系统）'!F5+'武隆污水（不上系统）'!F6 -> 1.134038e+08 | W4: ='武隆污水（不上系统）'!G5+'武隆污水（不上系统）'!G6 -> 0 | X4: ='武隆污水（不上系统）'!H5+'武隆污水（不上系统）'!H6 -> 0 | Y4: =SUM(U4:X4) -> 1.154038e+08 | Z4: =U4/1.06+V4/1.09+W4/1.13+X4/1.06 -> 1.0592697e+08 | AA4: ='武隆污水（不上系统）'!G12+'武隆污水（不上系统）'!G13 -> 1.149538e+08 | AB4: ='武隆污水（不上系统）'!C12 -> 1.134038e+08 | AC4: ='武隆污水（不上系统）'!S12+'武隆污水（不上系统）'!S13 -> 1.0470548e+08 | AD4: ='武隆污水（不上系统）'!O12 -> 1.0324322e+08 | AE4: ='武隆污水（不上系统）'!M12+'武隆污水（不上系统）'!M13 -> 1.149538e+08 | AF4: ='武隆污水（不上系统）'!I12 -> 1.134038e+08 | AG4: ='武隆污水（不上系统）'!T12+'武隆污水（不上系统）'!T13 -> 1.149538e+08 | AH4: ='武隆污水（不上系统）'!I102 -> 460219.88 | AI4: ='武隆污水（不上系统）'!I103 -> -31159.52 | AJ4: ='武隆污水（不上系统）'!E98+'武隆污水（不上系统）'!F98+'武隆污水（不上系统）'!G98+'武隆污水（不上系统）'!H98+'武隆污水（不上系统）'!J98+'武隆污水（不上系统）'!K98 -> 356700.42 | AK4: ='武隆污水（不上系统）'!D98 -> 35350.07 | AL4: ='武隆污水（不上系统）'!K4 -> 0.027878598 | AM4: ='武隆污水（不上系统）'!N4 -> 经计部 | AN4: ='武隆污水（不上系统）'!O4 -> 生态环境院 | AO4: ='武隆污水（不上系统）'!S4 -> 0 | AP4: ='武隆污水（不上系统）'!T4 -> 0 | AQ4: ='武隆污水（不上系统）'!U4 -> 0 | AR4: ='武隆污水（不上系统）'!V4 -> 市政 | AS4: ='武隆污水（不上系统）'!W4 -> 重庆市武隆区 | AT4: ='武隆污水（不上系统）'!X4 -> 竣工未决算 | AV4: ='武隆污水（不上系统）'!E133 -> 0 | AW4: =AV4/1.09 -> 0 | AX4: =AW4/#REF!*#REF! -> #REF! | BA4: =(AU4-AY4)+(AX4-AU4/1.09) -> #REF! | BB4: =AV4-AZ4 -> 0 | BC4: {=INDEX(账面数据!$A$1:$BB$10000,MATCH($B4,账面数据!$A:$A,0),MATCH(BC$2,账面数据!$1:$1,0))} -> 0 | BD4: {=INDEX(账面数据!$A$1:$BB$10000,MATCH($B4,账面数据!$A:$A,0),MATCH(BD$2,账面数据!$1:$1,0))} -> 0 | BE4: {=INDEX(账面数据!$A$1:$BB$10000,MATCH($B4,账面数据!$A:$A,0),MATCH(BE$2,账面数据!$1:$1,0))} -> 0 | BF4: {=INDEX(账面数据!$A$1:$BB$10000,MATCH($B4,账面数据!$A:$A,0),MATCH(BF$2,账面数据!$1:$1,0))} -> 0 | BG4: {=INDEX(账面数据!$A$1:$BB$10000,MATCH($B4,账面数据!$A:$A,0),MATCH(BG$2,账面数据!$1:$1,0))} -> 0 | BH4: {=INDEX(账面数据!$A$1:$BB$10000,MATCH($B4,账面数据!$A:$A,0),MATCH(BH$2,账面数据!$1:$1,0))} -> 0 | BI4: {=INDEX(账面数据!$A$1:$BB$10000,MATCH($B4,账面数据!$A:$A,0),MATCH(BI$2,账面数据!$1:$1,0))} -> 0 | BJ4: {=INDEX(账面数据!$A$1:$BB$10000,MATCH($B4,账面数据!$A:$A,0),MATCH(BJ$2,账面数据!$1:$1,0))} -> 0 | ... CQ4: {=INDEX(账面数据!$A$1:$BB$10000,MATCH($B4,账面数据!$A:$A,0),MATCH(CQ$2,账面数据!$1:$1,0))} -> 0 | CR4: =L4-T4-BC4-BF4-BM4-BN4+BQ4-BR4 -> 0 | CS4: =M4-S4-BR4-BS4 -> 0 | CT4: =AD4/K4*J4-P4 -> 0 | CU4: =AA4-AG4-BO4+BP4-BX4-BU4+BD4 -> 0 | CV4: =N4*(1-AL4)-AB4 -> 0 | CW4: =(R4-AF4)/1.09*0.02-AK4 -> 24323.431 | CX4: =BC4+(CN4-CO4)-BQ4 -> 0 | CY4: =L4/H4-AA4/Y4 -> 0.0038993517 | CZ4: 未缴纳税金 | DA4: 未办理外经证，8月底前预缴税金 | DB4: 环研院杨琳休假，计划于9.1-9.15日之间预缴
A5: =攀枝花大渡口!L4 -> 中铁二院攀枝花市大渡口污水处理厂提标升级改造工程EPC项目部 | B5: =攀枝花大渡口!M4 -> 攀枝花市大渡口污水处理厂提标升级改造工程项目勘察设计材料及设备采购施工总承包 | C5: =攀枝花大渡口!E4 -> 1520000 | D5: =攀枝花大渡口!F4 -> 13053600 | E5: =攀枝花大渡口!G4 -> 12326400 | F5: =攀枝花大渡口!H4 -> 0 | G5: =攀枝花大渡口!I4 -> 0 | H5: =SUM(C5:G5) -> 26900000 | I5: =C5/1.06+D5/1.09+E5/1.13+F5/1.06+G5/1.06 -> 24318061 | J5: =攀枝花大渡口!V12 -> 11975780 | K5: =攀枝花大渡口!W12 -> 11712313 | L5: =攀枝花大渡口!G12 -> 21835735 | M5: =攀枝花大渡口!H18 -> 2148318.6 | N5: =攀枝花大渡口!C12 -> 8466630 | O5: =攀枝花大渡口!S12 -> 22432092 | P5: =攀枝花大渡口!O12 -> 10512226 | Q5: =攀枝花大渡口!M12 -> 21853450 | R5: =攀枝花大渡口!I12 -> 8788345 | S5: =攀枝花大渡口!X18 -> 2157644.7 | T5: =攀枝花大渡口!T12 -> 21853450 | U5: =攀枝花大渡口!E6 -> 220000 | V5: =攀枝花大渡口!F5+攀枝花大渡口!F7 -> 12766421 | W5: =攀枝花大渡口!G5+攀枝花大渡口!G7 -> 12055219 | X5: =攀枝花大渡口!H5+攀枝花大渡口!H7 -> 0 | Y5: =SUM(U5:X5) -> 25041640 | Z5: =U5/1.06+V5/1.09+W5/1.13+X5/1.06 -> 22588195 | AA5: =攀枝花大渡口!G13+攀枝花大渡口!G14+攀枝花大渡口!G15 -> 20719065 | AB5: =攀枝花大渡口!C13 -> 10060410 | AC5: =攀枝花大渡口!S13+攀枝花大渡口!S14 -> 9437281.6 | AD5: =攀枝花大渡口!O13 -> 9229734.4 | AE5: =攀枝花大渡口!M13+攀枝花大渡口!M14 -> 9964771.5 | AF5: =攀枝花大渡口!I12 -> 8788345 | AG5: =攀枝花大渡口!T13+攀枝花大渡口!T14+攀枝花大渡口!T15 -> 20403427 | AH5: =攀枝花大渡口!I98 -> 57664.54 | AI5: =攀枝花大渡口!I99 -> -10160.24 | AJ5: =攀枝花大渡口!E94+攀枝花大渡口!F94+攀枝花大渡口!G94+攀枝花大渡口!H94+攀枝花大渡口!J94+攀枝花大渡口!K94 -> 8070 | AK5: =攀枝花大渡口!D94 -> 0 | AL5: =攀枝花大渡口!K4 -> 0.022 | AM5: =攀枝花大渡口!N4 -> 经计部 | AN5: =攀枝花大渡口!O4 -> 生态环境院 | AO5: =攀枝花大渡口!S4 -> 0 | AP5: =攀枝花大渡口!T4 -> 0 | AQ5: =攀枝花大渡口!U4 -> 0 | AR5: =攀枝花大渡口!V4 -> 市政 | AS5: =攀枝花大渡口!W4 -> 四川省攀枝花市 | AT5: =攀枝花大渡口!X4 -> 收尾 | AV5: =攀枝花大渡口!E129 -> -1780045.9 | AW5: =AV5/1.09 -> -1633069.7 | AX5: =AW5/#REF!*#REF! -> #REF! | BA5: =(AU5-AY5)+(AX5-AU5/1.09) -> #REF! | BB5: =AV5-AZ5 -> -1780045.9 | BC5: {=INDEX(账面数据!$A$1:$BB$10000,MATCH($B5,账面数据!$A:$A,0),MATCH(BC$2,账面数据!$1:$1,0))} -> 304000 | BD5: {=INDEX(账面数据!$A$1:$BB$10000,MATCH($B5,账面数据!$A:$A,0),MATCH(BD$2,账面数据!$1:$1,0))} -> 314638 | BE5: {=INDEX(账面数据!$A$1:$BB$10000,MATCH($B5,账面数据!$A:$A,0),MATCH(BE$2,账面数据!$1:$1,0))} -> 0 | BF5: {=INDEX(账面数据!$A$1:$BB$10000,MATCH($B5,账面数据!$A:$A,0),MATCH(BF$2,账面数据!$1:$1,0))} -> 0 | BG5: {=INDEX(账面数据!$A$1:$BB$10000,MATCH($B5,账面数据!$A:$A,0),MATCH(BG$2,账面数据!$1:$1,0))} -> 0 | BH5: {=INDEX(账面数据!$A$1:$BB$10000,MATCH($B5,账面数据!$A:$A,0),MATCH(BH$2,账面数据!$1:$1,0))} -> 0 | BI5: {=INDEX(账面数据!$A$1:$BB$10000,MATCH($B5,账面数据!$A:$A,0),MATCH(BI$2,账面数据!$1:$1,0))} -> 0 | BJ5: {=INDEX(账面数据!$A$1:$BB$10000,MATCH($B5,账面数据!$A:$A,0),MATCH(BJ$2,账面数据!$1:$1,0))} -> 0 | ... CQ5: {=INDEX(账面数据!$A$1:$BB$10000,MATCH($B5,账面数据!$A:$A,0),MATCH(CQ$2,账面数据!$1:$1,0))} -> 0 | CR5: =L5-T5-BC5-BF5-BM5-BN5+BQ5-BR5 -> 0 | CS5: =M5-S5-BR5-BS5 -> -2.9831426e-10 | CT5: =AD5/K5*J5-P5 -> -1074869.7 | CU5: =AA5-AG5-BO5+BP5-BX5-BU5+BD5 -> 2.4447218e-09 | CV5: =N5*(1-AL5)-AB5 -> -1780045.9 | CW5: =(R5-AF5)/1.09*0.02-AK5 -> 0 | CX5: =BC5+(CN5-CO5)-BQ5 -> 2726960.5 | CY5: =L5/H5-AA5/Y5 -> -0.015647163 | CZ5: 1、业主无验工计价，验工未列账； 2、施工多确认收入 | DA5: 1、8月1月前补充预缴税金销售额和抵扣额 | DB5: 已完成
A6: =攀枝花小沙坝!L4 -> 中铁二院攀枝花小沙坝污水处理厂改扩建EPC项目部 | B6: =攀枝花小沙坝!M4 -> 攀枝花小沙坝污水处理厂改扩建工程勘察-设计-采购-施工总承包合同 | C6: =攀枝花小沙坝!E4 -> 3326600 | D6: =攀枝花小沙坝!F4 -> 50118040 | E6: =攀枝花小沙坝!G4 -> 42060960 | F6: =攀枝花小沙坝!H4 -> 0 | G6: =攀枝花小沙坝!I4 -> 0 | H6: =SUM(C6:G6) -> 95505600 | I6: =C6/1.06+D6/1.09+E6/1.13+F6/1.06+G6/1.06 -> 86340244 | J6: =攀枝花小沙坝!V13 -> 45979853 | K6: =攀枝花小沙坝!W13 -> 45060256 | L6: =攀枝花小沙坝!G13 -> 81784714 | M6: =攀枝花小沙坝!H19 -> 8074712.7 | N6: =攀枝花小沙坝!C13 -> 35095447 | O6: =攀枝花小沙坝!S13 -> 77565026 | P6: =攀枝花小沙坝!O13 -> 36052683 | Q6: =攀枝花小沙坝!M13 -> 81119394 | R6: =攀枝花小沙坝!I13 -> 35095447 | S6: =攀枝花小沙坝!X19 -> 8037053.1 | T6: =攀枝花小沙坝!T13 -> 81119394 | U6: =攀枝花小沙坝!E6+攀枝花小沙坝!E8 -> 700000 | V6: =攀枝花小沙坝!F5 -> 49115679 | W6: =攀枝花小沙坝!G6+攀枝花小沙坝!G8 -> 41219741 | X6: =攀枝花小沙坝!H6+攀枝花小沙坝!H8 -> 0 | Y6: =SUM(U6:X6) -> 91035420 | Z6: =U6/1.06+V6/1.09+W6/1.13+X6/1.06 -> 82198280 | AA6: =攀枝花小沙坝!G14+攀枝花小沙坝!G15+攀枝花小沙坝!G16+攀枝花小沙坝!G17 -> 76850631 | AB6: =攀枝花小沙坝!C14 -> 34581733 | AC6: =攀枝花小沙坝!S14+攀枝花小沙坝!S15 -> 69061352 | AD6: =攀枝花小沙坝!O14 -> 31726361 | AE6: =攀枝花小沙坝!M14+攀枝花小沙坝!M15 -> 76888952 | AF6: =攀枝花小沙坝!I14 -> 34442715 | AG6: =攀枝花小沙坝!T14+攀枝花小沙坝!T15+攀枝花小沙坝!T16+攀枝花小沙坝!T17 -> 78018950 | AH6: =攀枝花小沙坝!I99 -> 396012.18 | AI6: =攀枝花小沙坝!I100 -> -23435.28 | AJ6: =攀枝花小沙坝!E95+攀枝花小沙坝!F95+攀枝花小沙坝!G95+攀枝花小沙坝!H95+攀枝花小沙坝!J95+攀枝花小沙坝!K95 -> 30088.9 | AK6: =攀枝花小沙坝!D95 -> 11976.73 | AL6: =攀枝花小沙坝!K4 -> 0.02 | AM6: =攀枝花小沙坝!N4 -> 经计部 | AN6: =攀枝花小沙坝!O4 -> 生态环境院 | AO6: =攀枝花小沙坝!S4 -> 0 | AP6: =攀枝花小沙坝!T4 -> 0 | AQ6: =攀枝花小沙坝!U4 -> 0 | AR6: =攀枝花小沙坝!V4 -> 市政 | AS6: =攀枝花小沙坝!W4 -> 四川省攀枝花市 | AT6: =攀枝花小沙坝!X4 -> 收尾 | AV6: =攀枝花小沙坝!E130 -> -188195.35 | AW6: =AV6/1.09 -> -172656.28 | AX6: =AW6/#REF!*#REF! -> #REF! | BA6: =(AU6-AY6)+(AX6-AU6/1.09) -> #REF! | BB6: =AV6-AZ6 -> -188195.35 | BC6: {=INDEX(账面数据!$A$1:$BB$10000,MATCH($B6,账面数据!$A:$A,0),MATCH(BC$2,账面数据!$1:$1,0))} -> 665320 | BD6: {=INDEX(账面数据!$A$1:$BB$10000,MATCH($B6,账面数据!$A:$A,0),MATCH(BD$2,账面数据!$1:$1,0))} -> 1307339.1 | BE6: {=INDEX(账面数据!$A$1:$BB$10000,MATCH($B6,账面数据!$A:$A,0),MATCH(BE$2,账面数据!$1:$1,0))} -> 0 | BF6: {=INDEX(账面数据!$A$1:$BB$10000,MATCH($B6,账面数据!$A:$A,0),MATCH(BF$2,账面数据!$1:$1,0))} -> 0 | BG6: {=INDEX(账面数据!$A$1:$BB$10000,MATCH($B6,账面数据!$A:$A,0),MATCH(BG$2,账面数据!$1:$1,0))} -> 0 | BH6: {=INDEX(账面数据!$A$1:$BB$10000,MATCH($B6,账面数据!$A:$A,0),MATCH(BH$2,账面数据!$1:$1,0))} -> 0 | BI6: {=INDEX(账面数据!$A$1:$BB$10000,MATCH($B6,账面数据!$A:$A,0),MATCH(BI$2,账面数据!$1:$1,0))} -> 0 | BJ6: {=INDEX(账面数据!$A$1:$BB$10000,MATCH($B6,账面数据!$A:$A,0),MATCH(BJ$2,账面数据!$1:$1,0))} -> 0 | ... BQ6: {=INDEX(账面数据!$A$1:$BB$10000,MATCH($B6,账面数据!$A:$A,0),MATCH(BQ$2,账面数据!$1:$1,0))} -> 0 | BR6: =INDEX(账面数据!$A$1:$BB$10000,MATCH($B6,账面数据!$A:$A,0),MATCH(BR$2,账面数据!$1:$1,0)) -> 0 | BS6: {=INDEX(账面数据!$A$1:$BB$10000,MATCH($B6,账面数据!$A:$A,0),MATCH(BS$2,账面数据!$1:$1,0))} -> 37659.62 | BT6: {=INDEX(账面数据!$A$1:$BB$10000,MATCH($B6,账面数据!$A:$A,0),MATCH(BT$2,账面数据!$1:$1,0))} -> 0 | BU6: {=INDEX(账面数据!$A$1:$BB$10000,MATCH($B6,账面数据!$A:$A,0),MATCH(BU$2,账面数据!$1:$1,0))} -> 0 | BV6: {=INDEX(账面数据!$A$1:$BB$10000,MATCH($B6,账面数据!$A:$A,0),MATCH(BV$2,账面数据!$1:$1,0))} -> 0 | BW6: {=INDEX(账面数据!$A$1:$BB$10000,MATCH($B6,账面数据!$A:$A,0),MATCH(BW$2,账面数据!$1:$1,0))} -> 0 | BX6: {=INDEX(账面数据!$A$1:$BB$10000,MATCH($B6,账面数据!$A:$A,0),MATCH(BX$2,账面数据!$1:$1,0))} -> 0 | BY6: {=INDEX(账面数据!$A$1:$BB$10000,MATCH($B6,账面数据!$A:$A,0),MATCH(BY$2,账面数据!$1:$1,0))} -> 0 | BZ6: {=INDEX(账面数据!$A$1:$BB$10000,MATCH($B6,账面数据!$A:$A,0),MATCH(BZ$2,账面数据!$1:$1,0))} -> 0 | ... CQ6: {=INDEX(账面数据!$A$1:$BB$10000,MATCH($B6,账面数据!$A:$A,0),MATCH(CQ$2,账面数据!$1:$1,0))} -> 0 | CR6: =L6-T6-BC6-BF6-BM6-BN6+BQ6-BR6 -> 0 | CS6: =M6-S6-BR6-BS6 -> 0.010000004 | CT6: =AD6/K6*J6-P6 -> -3678845.2 | CU6: =AA6-AG6-BO6+BP6-BX6-BU6+BD6 -> -3.0267984e-09 | CV6: =N6*(1-AL6)-AB6 -> -188195.35 | CW6: =(R6-AF6)/1.09*0.02-AK6 -> 0.011284404 | CX6: =BC6+(CN6-CO6)-BQ6 -> 4520345 | CY6: =L6/H6-AA6/Y6 -> 0.012150374 | CZ6: 1、业主无验工计价，验工未列账； 2、施工多确认收入 | DA6: 1、8月1月前补充预缴税金销售额和抵扣额 | DB6: 已完成
A7: =攀枝花炳草岗!L4 -> 中铁二院攀枝花市炳草岗污水处理厂提标升级改造工程EPC项目部 | B7: =攀枝花炳草岗!M4 -> 攀枝花市炳草岗污水处理厂提标升级改造工程勘察设计-材料及设备采购-施工总承包 | C7: =攀枝花炳草岗!E4 -> 3010000 | D7: =攀枝花炳草岗!F4 -> 34064400 | E7: =攀枝花炳草岗!G4 -> 26215600 | F7: =攀枝花炳草岗!H4 -> 0 | G7: =攀枝花炳草岗!I4 -> 0 | H7: =SUM(C7:G7) -> 63290000 | I7: =C7/1.06+D7/1.09+E7/1.13+F7/1.06+G7/1.06 -> 57291012 | J7: =攀枝花炳草岗!V13 -> 31251743 | K7: =攀枝花炳草岗!W13 -> 30564205 | L7: =攀枝花炳草岗!G13 -> 53147955 | M7: =攀枝花炳草岗!H19 -> 4902419.7 | N7: =攀枝花炳草岗!C13 -> 31902290 | O7: =攀枝花炳草岗!S13 -> 50053853 | P7: =攀枝花炳草岗!O13 -> 31076474 | Q7: =攀枝花炳草岗!M13 -> 54545955 | R7: =攀枝花炳草岗!I13 -> 33902290 | S7: =攀枝花炳草岗!X19 -> 5033481.9 | T7: =攀枝花炳草岗!T13 -> 54545955 | U7: =攀枝花炳草岗!E6+攀枝花炳草岗!E7 -> 940000 | V7: =攀枝花炳草岗!F5+攀枝花炳草岗!F8 -> 33314983 | W7: =攀枝花炳草岗!G5+攀枝花炳草岗!G8 -> 24470147 | X7: =攀枝花炳草岗!H5+攀枝花炳草岗!H8 -> 0 | Y7: =SUM(U7:X7) -> 58725130 | Z7: =U7/1.06+V7/1.09+W7/1.13+X7/1.06 -> 53105994 | AA7: =攀枝花炳草岗!G14+攀枝花炳草岗!G15+攀枝花炳草岗!G16+攀枝花炳草岗!G17 -> 51906920 | AB7: =攀枝花炳草岗!C14 -> 29945306 | AC7: =攀枝花炳草岗!S14+攀枝花炳草岗!S15 -> 27935022 | AD7: =攀枝花炳草岗!O14 -> 27472758 | AE7: =攀枝花炳草岗!M14+攀枝花炳草岗!M15 -> 30435306 | AF7: =攀枝花炳草岗!I14 -> 29945306 | AG7: =攀枝花炳草岗!T14+攀枝花炳草岗!T15+攀枝花炳草岗!T16++攀枝花炳草岗!T17 -> 51840920 | AH7: =攀枝花炳草岗!I99 -> 226992.11 | AI7: =攀枝花炳草岗!I100 -> -18096.88 | AJ7: =攀枝花炳草岗!E95+攀枝花炳草岗!F95+攀枝花炳草岗!G95+攀枝花炳草岗!H95+攀枝花炳草岗!J95+攀枝花炳草岗!K95 -> 40390.33 | AK7: =攀枝花炳草岗!D95 -> 97821.92 | AL7: =攀枝花炳草岗!K4 -> 0.022 | AM7: =攀枝花炳草岗!N4 -> 生态环境院 | AN7: =攀枝花炳草岗!O4 -> 生态环境院 | AO7: =攀枝花炳草岗!S4 -> 0 | AP7: =攀枝花炳草岗!T4 -> 0 | AQ7: =攀枝花炳草岗!U4 -> 0 | AR7: =攀枝花炳草岗!V4 -> 市政 | AS7: =攀枝花炳草岗!W4 -> 四川省攀枝花市 | AT7: =攀枝花炳草岗!X4 -> 收尾 | AV7: =攀枝花炳草岗!E130 -> 1255133.6 | AW7: =AV7/1.09 -> 1151498.7 | AX7: =AW7/#REF!*#REF! -> #REF! | BA7: =(AU7-AY7)+(AX7-AU7/1.09) -> #REF! | BB7: =AV7-AZ7 -> 1255133.6 | BC7: {=INDEX(账面数据!$A$1:$BB$10000,MATCH($B7,账面数据!$A:$A,0),MATCH(BC$2,账面数据!$1:$1,0))} -> -1295271.4 | BD7: {=INDEX(账面数据!$A$1:$BB$10000,MATCH($B7,账面数据!$A:$A,0),MATCH(BD$2,账面数据!$1:$1,0))} -> 0 | BE7: {=INDEX(账面数据!$A$1:$BB$10000,MATCH($B7,账面数据!$A:$A,0),MATCH(BE$2,账面数据!$1:$1,0))} -> 0 | BF7: {=INDEX(账面数据!$A$1:$BB$10000,MATCH($B7,账面数据!$A:$A,0),MATCH(BF$2,账面数据!$1:$1,0))} -> 0 | BG7: {=INDEX(账面数据!$A$1:$BB$10000,MATCH($B7,账面数据!$A:$A,0),MATCH(BG$2,账面数据!$1:$1,0))} -> 0 | BH7: {=INDEX(账面数据!$A$1:$BB$10000,MATCH($B7,账面数据!$A:$A,0),MATCH(BH$2,账面数据!$1:$1,0))} -> 0 | BI7: {=INDEX(账面数据!$A$1:$BB$10000,MATCH($B7,账面数据!$A:$A,0),MATCH(BI$2,账面数据!$1:$1,0))} -> 0 | BJ7: {=INDEX(账面数据!$A$1:$BB$10000,MATCH($B7,账面数据!$A:$A,0),MATCH(BJ$2,账面数据!$1:$1,0))} -> 0 | ... BQ7: {=INDEX(账面数据!$A$1:$BB$10000,MATCH($B7,账面数据!$A:$A,0),MATCH(BQ$2,账面数据!$1:$1,0))} -> 0 | BR7: =INDEX(账面数据!$A$1:$BB$10000,MATCH($B7,账面数据!$A:$A,0),MATCH(BR$2,账面数据!$1:$1,0)) -> -102728.59 | BS7: {=INDEX(账面数据!$A$1:$BB$10000,MATCH($B7,账面数据!$A:$A,0),MATCH(BS$2,账面数据!$1:$1,0))} -> -28333.55 | BT7: {=INDEX(账面数据!$A$1:$BB$10000,MATCH($B7,账面数据!$A:$A,0),MATCH(BT$2,账面数据!$1:$1,0))} -> 0 | BU7: {=INDEX(账面数据!$A$1:$BB$10000,MATCH($B7,账面数据!$A:$A,0),MATCH(BU$2,账面数据!$1:$1,0))} -> 0 | BV7: {=INDEX(账面数据!$A$1:$BB$10000,MATCH($B7,账面数据!$A:$A,0),MATCH(BV$2,账面数据!$1:$1,0))} -> 0 | BW7: {=INDEX(账面数据!$A$1:$BB$10000,MATCH($B7,账面数据!$A:$A,0),MATCH(BW$2,账面数据!$1:$1,0))} -> 0 | BX7: {=INDEX(账面数据!$A$1:$BB$10000,MATCH($B7,账面数据!$A:$A,0),MATCH(BX$2,账面数据!$1:$1,0))} -> 0 | BY7: {=INDEX(账面数据!$A$1:$BB$10000,MATCH($B7,账面数据!$A:$A,0),MATCH(BY$2,账面数据!$1:$1,0))} -> 0 | BZ7: {=INDEX(账面数据!$A$1:$BB$10000,MATCH($B7,账面数据!$A:$A,0),MATCH(BZ$2,账面数据!$1:$1,0))} -> 0 | ... CQ7: {=INDEX(账面数据!$A$1:$BB$10000,MATCH($B7,账面数据!$A:$A,0),MATCH(CQ$2,账面数据!$1:$1,0))} -> 0 | CR7: =L7-T7-BC7-BF7-BM7-BN7+BQ7-BR7 -> -0.0020354018 | CS7: =M7-S7-BR7-BS7 -> 3.3105607e-10 | CT7: =AD7/K7*J7-P7 -> -2985719.8 | CU7: =AA7-AG7-BO7+BP7-BX7-BU7+BD7 -> 0.00097350776 | CV7: =N7*(1-AL7)-AB7 -> 1255133.6 | CW7: =(R7-AF7)/1.09*0.02-AK7 -> -25216.709 | CX7: =BC7+(CN7-CO7)-BQ7 -> 513046.79 | CY7: =L7/H7-AA7/Y7 -> -0.044143408 | CZ7: 1、分包方未足额验工计价； 2、施工多确认收入 | DA7: 1、8月1月前补充预缴税金销售额和抵扣额； 2、8月1日前应收账款-预收账款增值税调整至合同负债-预收账款增值税 | DB7: 已完成
A8: ='XX项目 (6)'!L4 -> 来源于“共享系统”系统管理-权限管理-人员管理 | B8: ='XX项目 (6)'!M4 -> 来源于“共享系统”系统管理-权限管理-人员管理 | C8: ='XX项目 (6)'!E4 -> 0 | D8: ='XX项目 (6)'!F4 -> 0 | E8: ='XX项目 (6)'!G4 -> 0 | F8: ='XX项目 (6)'!H4 -> 0 | G8: ='XX项目 (6)'!I4 -> 0 | H8: =SUM(C8:G8) -> 0 | I8: =C8/1.06+D8/1.09+E8/1.13+F8/1.06+G8/1.06 -> 0 | L8: ='XX项目 (6)'!G11 -> 0 | O8: ='XX项目 (6)'!S11 -> 0 | Q8: ='XX项目 (6)'!M11 -> 0 | T8: ='XX项目 (6)'!T11 -> 0 | U8: ='XX项目 (6)'!E5+'XX项目 (6)'!E6 -> 0 | V8: ='XX项目 (6)'!F5+'XX项目 (6)'!F6 -> 0 | W8: ='XX项目 (6)'!G5+'XX项目 (6)'!G6 -> 0 | X8: ='XX项目 (6)'!H5+'XX项目 (6)'!H6 -> 0 | Y8: =SUM(U8:X8) -> 0 | Z8: =U8/1.06+V8/1.09+W8/1.13+X8/1.06 -> 0 | AA8: ='XX项目 (6)'!G12+'XX项目 (6)'!G13 -> 0 | AC8: ='XX项目 (6)'!S12+'XX项目 (6)'!S13 -> 0 | AE8: ='XX项目 (6)'!M12+'XX项目 (6)'!M13 -> 0 | AG8: ='XX项目 (6)'!T12+'XX项目 (6)'!T13 -> 0 | AH8: ='XX项目 (6)'!I97 -> 0 | AI8: ='XX项目 (6)'!I98 -> 0 | AJ8: ='XX项目 (6)'!E93+'XX项目 (6)'!F93+'XX项目 (6)'!G93+'XX项目 (6)'!H93+'XX项目 (6)'!J93+'XX项目 (6)'!K93 -> 0 | AL8: ='XX项目 (6)'!K4 -> #DIV/0! | AM8: ='XX项目 (6)'!N4 -> 主合同编号中的单位 | AN8: ='XX项目 (6)'!O4 -> 实际管理单位 | AO8: ='XX项目 (6)'!S4 -> 0 | AP8: ='XX项目 (6)'!T4 -> 0 | AQ8: ='XX项目 (6)'!U4 -> 0 | AR8: ='XX项目 (6)'!V4 -> 0 | AS8: ='XX项目 (6)'!W4 -> 0 | AT8: ='XX项目 (6)'!X4 -> 0 | AV8: ='XX项目 (6)'!E128 -> #DIV/0! | AW8: =AV8/1.09 -> #DIV/0! | AX8: =AW8/#REF!*#REF! -> #DIV/0! | BA8: =(AU8-AY8)+(AX8-AU8/1.09) -> #DIV/0! | BB8: =AV8-AZ8 -> #DIV/0! | BC8: {=INDEX(账面数据!$A$1:$BB$10000,MATCH($B8,账面数据!$A:$A,0),MATCH(BC$2,账面数据!$1:$1,0))} -> #N/A | BD8: {=INDEX(账面数据!$A$1:$BB$10000,MATCH($B8,账面数据!$A:$A,0),MATCH(BD$2,账面数据!$1:$1,0))} -> #N/A | BE8: {=INDEX(账面数据!$A$1:$BB$10000,MATCH($B8,账面数据!$A:$A,0),MATCH(BE$2,账面数据!$1:$1,0))} -> #N/A | BF8: {=INDEX(账面数据!$A$1:$BB$10000,MATCH($B8,账面数据!$A:$A,0),MATCH(BF$2,账面数据!$1:$1,0))} -> #N/A | BG8: {=INDEX(账面数据!$A$1:$BB$10000,MATCH($B8,账面数据!$A:$A,0),MATCH(BG$2,账面数据!$1:$1,0))} -> #N/A | BH8: {=INDEX(账面数据!$A$1:$BB$10000,MATCH($B8,账面数据!$A:$A,0),MATCH(BH$2,账面数据!$1:$1,0))} -> #N/A | BI8: {=INDEX(账面数据!$A$1:$BB$10000,MATCH($B8,账面数据!$A:$A,0),MATCH(BI$2,账面数据!$1:$1,0))} -> #N/A | BJ8: {=INDEX(账面数据!$A$1:$BB$10000,MATCH($B8,账面数据!$A:$A,0),MATCH(BJ$2,账面数据!$1:$1,0))} -> #N/A | ... CQ8: {=INDEX(账面数据!$A$1:$BB$10000,MATCH($B8,账面数据!$A:$A,0),MATCH(CQ$2,账面数据!$1:$1,0))} -> #N/A | CR8: =L8-T8-BC8-BF8-BM8-BN8+BQ8-BR8 -> #N/A | CS8: =M8-S8-BR8-BS8 -> #N/A | CT8: =AD8/K8*J8-P8 -> #DIV/0! | CU8: =AA8-AG8-BO8+BP8-BX8-BU8+BD8 -> #N/A | CV8: =N8*(1-AL8)-AB8 -> #DIV/0! | CW8: =(R8-AF8)/1.09*0.02-AK8 -> 0 | CX8: =BC8+(CN8-CO8)-BQ8 -> #N/A | CY8: =L8/H8-AA8/Y8 -> #DIV/0!
A9: ='XX项目 (7)'!L4 -> 来源于“共享系统”系统管理-权限管理-人员管理 | B9: ='XX项目 (7)'!M4 -> 来源于“共享系统”系统管理-权限管理-人员管理 | C9: ='XX项目 (7)'!E4 -> 0 | D9: ='XX项目 (7)'!F4 -> 0 | E9: ='XX项目 (7)'!G4 -> 0 | F9: ='XX项目 (7)'!H4 -> 0 | G9: ='XX项目 (7)'!I4 -> 0 | H9: =SUM(C9:G9) -> 0 | I9: =C9/1.06+D9/1.09+E9/1.13+F9/1.06+G9/1.06 -> 0 | L9: ='XX项目 (7)'!G11 -> 0 | O9: ='XX项目 (7)'!S11 -> 0 | Q9: ='XX项目 (7)'!M11 -> 0 | T9: ='XX项目 (7)'!T11 -> 0 | U9: ='XX项目 (7)'!E5+'XX项目 (7)'!E6 -> 0 | V9: ='XX项目 (7)'!F5+'XX项目 (7)'!F6 -> 0 | W9: ='XX项目 (7)'!G5+'XX项目 (7)'!G6 -> 0 | X9: ='XX项目 (7)'!H5+'XX项目 (7)'!H6 -> 0 | Y9: =SUM(U9:X9) -> 0 | Z9: =U9/1.06+V9/1.09+W9/1.13+X9/1.06 -> 0 | AA9: ='XX项目 (7)'!G12+'XX项目 (7)'!G13 -> 0 | AC9: ='XX项目 (7)'!S12+'XX项目 (7)'!S13 -> 0 | AE9: ='XX项目 (7)'!M12+'XX项目 (7)'!M13 -> 0 | AG9: ='XX项目 (7)'!T12+'XX项目 (7)'!T13 -> 0 | AH9: ='XX项目 (7)'!I97 -> 0 | AI9: ='XX项目 (7)'!I98 -> 0 | AJ9: ='XX项目 (7)'!E93+'XX项目 (7)'!F93+'XX项目 (7)'!G93+'XX项目 (7)'!H93+'XX项目 (7)'!J93+'XX项目 (7)'!K93 -> 0 | AL9: ='XX项目 (7)'!K4 -> #DIV/0! | AM9: ='XX项目 (7)'!N4 -> 主合同编号中的单位 | AN9: ='XX项目 (7)'!O4 -> 实际管理单位 | AO9: ='XX项目 (7)'!S4 -> 0 | AP9: ='XX项目 (7)'!T4 -> 0 | AQ9: ='XX项目 (7)'!U4 -> 0 | AR9: ='XX项目 (7)'!V4 -> 0 | AS9: ='XX项目 (7)'!W4 -> 0 | AT9: ='XX项目 (7)'!X4 -> 0 | AV9: ='XX项目 (7)'!E128 -> #DIV/0! | AW9: =AV9/1.09 -> #DIV/0! | AX9: =AW9/#REF!*#REF! -> #DIV/0! | BA9: =(AU9-AY9)+(AX9-AU9/1.09) -> #DIV/0! | BB9: =AV9-AZ9 -> #DIV/0! | BC9: {=INDEX(账面数据!$A$1:$BB$10000,MATCH($B9,账面数据!$A:$A,0),MATCH(BC$2,账面数据!$1:$1,0))} -> #N/A | BD9: {=INDEX(账面数据!$A$1:$BB$10000,MATCH($B9,账面数据!$A:$A,0),MATCH(BD$2,账面数据!$1:$1,0))} -> #N/A | BE9: {=INDEX(账面数据!$A$1:$BB$10000,MATCH($B9,账面数据!$A:$A,0),MATCH(BE$2,账面数据!$1:$1,0))} -> #N/A | BF9: {=INDEX(账面数据!$A$1:$BB$10000,MATCH($B9,账面数据!$A:$A,0),MATCH(BF$2,账面数据!$1:$1,0))} -> #N/A | BG9: {=INDEX(账面数据!$A$1:$BB$10000,MATCH($B9,账面数据!$A:$A,0),MATCH(BG$2,账面数据!$1:$1,0))} -> #N/A | BH9: {=INDEX(账面数据!$A$1:$BB$10000,MATCH($B9,账面数据!$A:$A,0),MATCH(BH$2,账面数据!$1:$1,0))} -> #N/A | BI9: {=INDEX(账面数据!$A$1:$BB$10000,MATCH($B9,账面数据!$A:$A,0),MATCH(BI$2,账面数据!$1:$1,0))} -> #N/A | BJ9: {=INDEX(账面数据!$A$1:$BB$10000,MATCH($B9,账面数据!$A:$A,0),MATCH(BJ$2,账面数据!$1:$1,0))} -> #N/A | ... CQ9: {=INDEX(账面数据!$A$1:$BB$10000,MATCH($B9,账面数据!$A:$A,0),MATCH(CQ$2,账面数据!$1:$1,0))} -> #N/A | CR9: =L9-T9-BC9-BF9-BM9-BN9+BQ9-BR9 -> #N/A | CS9: =M9-S9-BR9-BS9 -> #N/A | CT9: =AD9/K9*J9-P9 -> #DIV/0! | CU9: =AA9-AG9-BO9+BP9-BX9-BU9+BD9 -> #N/A | CV9: =N9*(1-AL9)-AB9 -> #DIV/0! | CW9: =(R9-AF9)/1.09*0.02-AK9 -> 0 | CX9: =BC9+(CN9-CO9)-BQ9 -> #N/A | CY9: =L9/H9-AA9/Y9 -> #DIV/0!
A10: ='XX项目 (8)'!L4 -> 来源于“共享系统”系统管理-权限管理-人员管理 | B10: ='XX项目 (8)'!M4 -> 来源于“共享系统”系统管理-权限管理-人员管理 | C10: ='XX项目 (8)'!E4 -> 0 | D10: ='XX项目 (8)'!F4 -> 0 | E10: ='XX项目 (8)'!G4 -> 0 | F10: ='XX项目 (8)'!H4 -> 0 | G10: ='XX项目 (8)'!I4 -> 0 | H10: =SUM(C10:G10) -> 0 | I10: =C10/1.06+D10/1.09+E10/1.13+F10/1.06+G10/1.06 -> 0 | L10: ='XX项目 (8)'!G11 -> 0 | O10: ='XX项目 (8)'!S11 -> 0 | Q10: ='XX项目 (8)'!M11 -> 0 | T10: ='XX项目 (8)'!T11 -> 0 | U10: ='XX项目 (8)'!E5+'XX项目 (8)'!E6 -> 0 | V10: ='XX项目 (8)'!F5+'XX项目 (8)'!F6 -> 0 | W10: ='XX项目 (8)'!G5+'XX项目 (8)'!G6 -> 0 | X10: ='XX项目 (8)'!H5+'XX项目 (8)'!H6 -> 0 | Y10: =SUM(U10:X10) -> 0 | Z10: =U10/1.06+V10/1.09+W10/1.13+X10/1.06 -> 0 | AA10: ='XX项目 (8)'!G12+'XX项目 (8)'!G13 -> 0 | AC10: ='XX项目 (8)'!S12+'XX项目 (8)'!S13 -> 0 | AE10: ='XX项目 (8)'!M12+'XX项目 (8)'!M13 -> 0 | AG10: ='XX项目 (8)'!T12+'XX项目 (8)'!T13 -> 0 | AH10: ='XX项目 (8)'!I97 -> 0 | AI10: ='XX项目 (8)'!I98 -> 0 | AJ10: ='XX项目 (8)'!E93+'XX项目 (8)'!F93+'XX项目 (8)'!G93+'XX项目 (8)'!H93+'XX项目 (8)'!J93+'XX项目 (8)'!K93 -> 0 | AL10: ='XX项目 (8)'!K4 -> #DIV/0! | AM10: ='XX项目 (8)'!N4 -> 主合同编号中的单位 | AN10: ='XX项目 (8)'!O4 -> 实际管理单位 | AO10: ='XX项目 (8)'!S4 -> 0 | AP10: ='XX项目 (8)'!T4 -> 0 | AQ10: ='XX项目 (8)'!U4 -> 0 | AR10: ='XX项目 (8)'!V4 -> 0 | AS10: ='XX项目 (8)'!W4 -> 0 | AT10: ='XX项目 (8)'!X4 -> 0 | AV10: ='XX项目 (8)'!E128 -> #DIV/0! | AW10: =AV10/1.09 -> #DIV/0! | AX10: =AW10/#REF!*#REF! -> #DIV/0! | BA10: =(AU10-AY10)+(AX10-AU10/1.09) -> #DIV/0! | BB10: =AV10-AZ10 -> #DIV/0! | BC10: {=INDEX(账面数据!$A$1:$BB$10000,MATCH($B10,账面数据!$A:$A,0),MATCH(BC$2,账面数据!$1:$1,0))} -> #N/A | BD10: {=INDEX(账面数据!$A$1:$BB$10000,MATCH($B10,账面数据!$A:$A,0),MATCH(BD$2,账面数据!$1:$1,0))} -> #N/A | BE10: {=INDEX(账面数据!$A$1:$BB$10000,MATCH($B10,账面数据!$A:$A,0),MATCH(BE$2,账面数据!$1:$1,0))} -> #N/A | BF10: {=INDEX(账面数据!$A$1:$BB$10000,MATCH($B10,账面数据!$A:$A,0),MATCH(BF$2,账面数据!$1:$1,0))} -> #N/A | BG10: {=INDEX(账面数据!$A$1:$BB$10000,MATCH($B10,账面数据!$A:$A,0),MATCH(BG$2,账面数据!$1:$1,0))} -> #N/A | BH10: {=INDEX(账面数据!$A$1:$BB$10000,MATCH($B10,账面数据!$A:$A,0),MATCH(BH$2,账面数据!$1:$1,0))} -> #N/A | BI10: {=INDEX(账面数据!$A$1:$BB$10000,MATCH($B10,账面数据!$A:$A,0),MATCH(BI$2,账面数据!$1:$1,0))} -> #N/A | BJ10: {=INDEX(账面数据!$A$1:$BB$10000,MATCH($B10,账面数据!$A:$A,0),MATCH(BJ$2,账面数据!$1:$1,0))} -> #N/A | ... CQ10: {=INDEX(账面数据!$A$1:$BB$10000,MATCH($B10,账面数据!$A:$A,0),MATCH(CQ$2,账面数据!$1:$1,0))} -> #N/A | CR10: =L10-T10-BC10-BF10-BM10-BN10+BQ10-BR10 -> #N/A | CS10: =M10-S10-BR10-BS10 -> #N/A | CT10: =AD10/K10*J10-P10 -> #DIV/0! | CU10: =AA10-AG10-BO10+BP10-BX10-BU10+BD10 -> #N/A | CV10: =N10*(1-AL10)-AB10 -> #DIV/0! | CW10: =(R10-AF10)/1.09*0.02-AK10 -> 0 | CX10: =BC10+(CN10-CO10)-BQ10 -> #N/A | CY10: =L10/H10-AA10/Y10 -> #DIV/0!
A11: ='XX项目 (9)'!L4 -> 来源于“共享系统”系统管理-权限管理-人员管理 | B11: ='XX项目 (9)'!M4 -> 来源于“共享系统”系统管理-权限管理-人员管理 | C11: ='XX项目 (9)'!E4 -> 0 | D11: ='XX项目 (9)'!F4 -> 0 | E11: ='XX项目 (9)'!G4 -> 0 | F11: ='XX项目 (9)'!H4 -> 0 | G11: ='XX项目 (9)'!I4 -> 0 | H11: =SUM(C11:G11) -> 0 | I11: =C11/1.06+D11/1.09+E11/1.13+F11/1.06+G11/1.06 -> 0 | L11: ='XX项目 (9)'!G11 -> 0 | O11: ='XX项目 (9)'!S11 -> 0 | Q11: ='XX项目 (9)'!M11 -> 0 | T11: ='XX项目 (9)'!T11 -> 0 | U11: ='XX项目 (9)'!E5+'XX项目 (9)'!E6 -> 0 | V11: ='XX项目 (9)'!F5+'XX项目 (9)'!F6 -> 0 | W11: ='XX项目 (9)'!G5+'XX项目 (9)'!G6 -> 0 | X11: ='XX项目 (9)'!H5+'XX项目 (9)'!H6 -> 0 | Y11: =SUM(U11:X11) -> 0 | Z11: =U11/1.06+V11/1.09+W11/1.13+X11/1.06 -> 0 | AA11: ='XX项目 (9)'!G12+'XX项目 (9)'!G13 -> 0 | AC11: ='XX项目 (9)'!S12+'XX项目 (9)'!S13 -> 0 | AE11: ='XX项目 (9)'!M12+'XX项目 (9)'!M13 -> 0 | AG11: ='XX项目 (9)'!T12+'XX项目 (9)'!T13 -> 0 | AH11: ='XX项目 (9)'!I97 -> 0 | AI11: ='XX项目 (9)'!I98 -> 0 | AJ11: ='XX项目 (9)'!E93+'XX项目 (9)'!F93+'XX项目 (9)'!G93+'XX项目 (9)'!H93+'XX项目 (9)'!J93+'XX项目 (9)'!K93 -> 0 | AL11: ='XX项目 (9)'!K4 -> #DIV/0! | AM11: ='XX项目 (9)'!N4 -> 主合同编号中的单位 | AN11: ='XX项目 (9)'!O4 -> 实际管理单位 | AO11: ='XX项目 (9)'!S4 -> 0 | AP11: ='XX项目 (9)'!T4 -> 0 | AQ11: ='XX项目 (9)'!U4 -> 0 | AR11: ='XX项目 (9)'!V4 -> 0 | AS11: ='XX项目 (9)'!W4 -> 0 | AT11: ='XX项目 (9)'!X4 -> 0 | AV11: ='XX项目 (9)'!E128 -> #DIV/0! | AW11: =AV11/1.09 -> #DIV/0! | AX11: =AW11/#REF!*#REF! -> #DIV/0! | BA11: =(AU11-AY11)+(AX11-AU11/1.09) -> #DIV/0! | BB11: =AV11-AZ11 -> #DIV/0! | BC11: {=INDEX(账面数据!$A$1:$BB$10000,MATCH($B11,账面数据!$A:$A,0),MATCH(BC$2,账面数据!$1:$1,0))} -> #N/A | BD11: {=INDEX(账面数据!$A$1:$BB$10000,MATCH($B11,账面数据!$A:$A,0),MATCH(BD$2,账面数据!$1:$1,0))} -> #N/A | BE11: {=INDEX(账面数据!$A$1:$BB$10000,MATCH($B11,账面数据!$A:$A,0),MATCH(BE$2,账面数据!$1:$1,0))} -> #N/A | BF11: {=INDEX(账面数据!$A$1:$BB$10000,MATCH($B11,账面数据!$A:$A,0),MATCH(BF$2,账面数据!$1:$1,0))} -> #N/A | BG11: {=INDEX(账面数据!$A$1:$BB$10000,MATCH($B11,账面数据!$A:$A,0),MATCH(BG$2,账面数据!$1:$1,0))} -> #N/A | BH11: {=INDEX(账面数据!$A$1:$BB$10000,MATCH($B11,账面数据!$A:$A,0),MATCH(BH$2,账面数据!$1:$1,0))} -> #N/A | BI11: {=INDEX(账面数据!$A$1:$BB$10000,MATCH($B11,账面数据!$A:$A,0),MATCH(BI$2,账面数据!$1:$1,0))} -> #N/A | BJ11: {=INDEX(账面数据!$A$1:$BB$10000,MATCH($B11,账面数据!$A:$A,0),MATCH(BJ$2,账面数据!$1:$1,0))} -> #N/A | ... CQ11: {=INDEX(账面数据!$A$1:$BB$10000,MATCH($B11,账面数据!$A:$A,0),MATCH(CQ$2,账面数据!$1:$1,0))} -> #N/A | CR11: =L11-T11-BC11-BF11-BM11-BN11+BQ11-BR11 -> #N/A | CS11: =M11-S11-BR11-BS11 -> #N/A | CT11: =AD11/K11*J11-P11 -> #DIV/0! | CU11: =AA11-AG11-BO11+BP11-BX11-BU11+BD11 -> #N/A | CV11: =N11*(1-AL11)-AB11 -> #DIV/0! | CW11: =(R11-AF11)/1.09*0.02-AK11 -> 0 | CX11: =BC11+(CN11-CO11)-BQ11 -> #N/A | CY11: =L11/H11-AA11/Y11 -> #DIV/0!
A12: ='XX项目 (10)'!L4 -> 来源于“共享系统”系统管理-权限管理-人员管理 | B12: ='XX项目 (10)'!M4 -> 来源于“共享系统”系统管理-权限管理-人员管理 | C12: ='XX项目 (10)'!E4 -> 0 | D12: ='XX项目 (10)'!F4 -> 0 | E12: ='XX项目 (10)'!G4 -> 0 | F12: ='XX项目 (10)'!H4 -> 0 | G12: ='XX项目 (10)'!I4 -> 0 | H12: =SUM(C12:G12) -> 0 | I12: =C12/1.06+D12/1.09+E12/1.13+F12/1.06+G12/1.06 -> 0 | L12: ='XX项目 (10)'!G11 -> 0 | O12: ='XX项目 (10)'!S11 -> 0 | Q12: ='XX项目 (10)'!M11 -> 0 | T12: ='XX项目 (10)'!T11 -> 0 | U12: ='XX项目 (10)'!E5+'XX项目 (10)'!E6 -> 0 | V12: ='XX项目 (10)'!F5+'XX项目 (10)'!F6 -> 0 | W12: ='XX项目 (10)'!G5+'XX项目 (10)'!G6 -> 0 | X12: ='XX项目 (10)'!H5+'XX项目 (10)'!H6 -> 0 | Y12: =SUM(U12:X12) -> 0 | Z12: =U12/1.06+V12/1.09+W12/1.13+X12/1.06 -> 0 | AA12: ='XX项目 (10)'!G12+'XX项目 (10)'!G13 -> 0 | AC12: ='XX项目 (10)'!S12+'XX项目 (10)'!S13 -> 0 | AE12: ='XX项目 (10)'!M12+'XX项目 (10)'!M13 -> 0 | AG12: ='XX项目 (10)'!T12+'XX项目 (10)'!T13 -> 0 | AH12: ='XX项目 (10)'!I97 -> 0 | AI12: ='XX项目 (10)'!I98 -> 0 | AJ12: ='XX项目 (10)'!E93+'XX项目 (10)'!F93+'XX项目 (10)'!G93+'XX项目 (10)'!H93+'XX项目 (10)'!J93+'XX项目 (10)'!K93 -> 0 | AL12: ='XX项目 (10)'!K4 -> #DIV/0! | AM12: ='XX项目 (10)'!N4 -> 主合同编号中的单位 | AN12: ='XX项目 (10)'!O4 -> 实际管理单位 | AO12: ='XX项目 (10)'!S4 -> 0 | AP12: ='XX项目 (10)'!T4 -> 0 | AQ12: ='XX项目 (10)'!U4 -> 0 | AR12: ='XX项目 (10)'!V4 -> 0 | AS12: ='XX项目 (10)'!W4 -> 0 | AT12: ='XX项目 (10)'!X4 -> 0 | AV12: ='XX项目 (10)'!E128 -> #DIV/0! | AW12: =AV12/1.09 -> #DIV/0! | AX12: =AW12/#REF!*#REF! -> #DIV/0! | BA12: =(AU12-AY12)+(AX12-AU12/1.09) -> #DIV/0! | BB12: =AV12-AZ12 -> #DIV/0! | BC12: {=INDEX(账面数据!$A$1:$BB$10000,MATCH($B12,账面数据!$A:$A,0),MATCH(BC$2,账面数据!$1:$1,0))} -> #N/A | BD12: {=INDEX(账面数据!$A$1:$BB$10000,MATCH($B12,账面数据!$A:$A,0),MATCH(BD$2,账面数据!$1:$1,0))} -> #N/A | BE12: {=INDEX(账面数据!$A$1:$BB$10000,MATCH($B12,账面数据!$A:$A,0),MATCH(BE$2,账面数据!$1:$1,0))} -> #N/A | BF12: {=INDEX(账面数据!$A$1:$BB$10000,MATCH($B12,账面数据!$A:$A,0),MATCH(BF$2,账面数据!$1:$1,0))} -> #N/A | BG12: {=INDEX(账面数据!$A$1:$BB$10000,MATCH($B12,账面数据!$A:$A,0),MATCH(BG$2,账面数据!$1:$1,0))} -> #N/A | BH12: {=INDEX(账面数据!$A$1:$BB$10000,MATCH($B12,账面数据!$A:$A,0),MATCH(BH$2,账面数据!$1:$1,0))} -> #N/A | BI12: {=INDEX(账面数据!$A$1:$BB$10000,MATCH($B12,账面数据!$A:$A,0),MATCH(BI$2,账面数据!$1:$1,0))} -> #N/A | BJ12: {=INDEX(账面数据!$A$1:$BB$10000,MATCH($B12,账面数据!$A:$A,0),MATCH(BJ$2,账面数据!$1:$1,0))} -> #N/A | ... CQ12: {=INDEX(账面数据!$A$1:$BB$10000,MATCH($B12,账面数据!$A:$A,0),MATCH(CQ$2,账面数据!$1:$1,0))} -> #N/A | CR12: =L12-T12-BC12-BF12-BM12-BN12+BQ12-BR12 -> #N/A | CS12: =M12-S12-BR12-BS12 -> #N/A | CT12: =AD12/K12*J12-P12 -> #DIV/0! | CU12: =AA12-AG12-BO12+BP12-BX12-BU12+BD12 -> #N/A | CV12: =N12*(1-AL12)-AB12 -> #DIV/0! | CW12: =(R12-AF12)/1.09*0.02-AK12 -> 0 | CX12: =BC12+(CN12-CO12)-BQ12 -> #N/A | CY12: =L12/H12-AA12/Y12 -> #DIV/0!
H13: =SUM(C13:G13) -> 0 | I13: =C13/1.06+D13/1.09+E13/1.13+F13/1.06+G13/1.06 -> 0 | Y13: =SUM(U13:X13) -> 0 | Z13: =U13/1.06+V13/1.09+W13/1.13+X13/1.06 -> 0
H14: =SUM(C14:G14) -> 0 | I14: =C14/1.06+D14/1.09+E14/1.13+F14/1.06+G14/1.06 -> 0 | Y14: =SUM(U14:X14) -> 0 | Z14: =U14/1.06+V14/1.09+W14/1.13+X14/1.06 -> 0
H15: =SUM(C15:G15) -> 0 | I15: =C15/1.06+D15/1.09+E15/1.13+F15/1.06+G15/1.06 -> 0 | Y15: =SUM(U15:X15) -> 0 | Z15: =U15/1.06+V15/1.09+W15/1.13+X15/1.06 -> 0
H16: =SUM(C16:G16) -> 0 | I16: =C16/1.06+D16/1.09+E16/1.13+F16/1.06+G16/1.06 -> 0 | Y16: =SUM(U16:X16) -> 0 | Z16: =U16/1.06+V16/1.09+W16/1.13+X16/1.06 -> 0
H17: =SUM(C17:G17) -> 0 | I17: =C17/1.06+D17/1.09+E17/1.13+F17/1.06+G17/1.06 -> 0 | Y17: =SUM(U17:X17) -> 0 | Z17: =U17/1.06+V17/1.09+W17/1.13+X17/1.06 -> 0
H18: =SUM(C18:G18) -> 0 | I18: =C18/1.06+D18/1.09+E18/1.13+F18/1.06+G18/1.06 -> 0 | Y18: =SUM(U18:X18) -> 0 | Z18: =U18/1.06+V18/1.09+W18/1.13+X18/1.06 -> 0
H19: =SUM(C19:G19) -> 0 | I19: =C19/1.06+D19/1.09+E19/1.13+F19/1.06+G19/1.06 -> 0 | Y19: =SUM(U19:X19) -> 0 | Z19: =U19/1.06+V19/1.09+W19/1.13+X19/1.06 -> 0
H20: =SUM(C20:G20) -> 0 | I20: =C20/1.06+D20/1.09+E20/1.13+F20/1.06+G20/1.06 -> 0 | Y20: =SUM(U20:X20) -> 0 | Z20: =U20/1.06+V20/1.09+W20/1.13+X20/1.06 -> 0 | AW20: =AU20/1.09 -> 0 | AX20: =AW20/#REF!*#REF! -> #REF! | BA20: =(AU20-AY20)+(AX20-AU20/1.09) -> #REF! | BB20: =AV20-AZ20 -> 0

Sheet 账面数据
A1: 项目名称 | B1: 1122应收账款 | C1: 1123预付款项 | D1: 1221其他应收款 | E1: 1221-04-03其他应收款-民工工资保证金 | F1: 1221-05其他应收款-预付款项转入 | G1: 1221-09其他应收款-应收押金 | H1: 1221-11其他应收款-应收押金 | I1: 1221-99其他应收款-其他 | J1: 1231坏账准备 | K1: 1484合同资产减值准备 | L1: 1483合同资产 | M1: 1531长期应收款 | N1: 2202应付账款 | O1: 2202-12应付账款-预付账款增值税 | P1: 2204合同负债 | Q1: 2204-10合同负债-预收账款增值税 | R1: 2221-06应交税费-待转销项税额 | S1: 2241其他应付款 | T1: 2241-01其他应付款-保证金 | U1: 2241-05其他应付款-应付押金 | V1: 2241-99其他应付款-其他 | W1: 2701长期应付款 | X1: 2701-05长期应付款-应付质量保证金 | Y1: 2701-99长期应付款-其他 | Z1: 5601-01-01-01合同履约成本-工程施工-合同成本-直接人工费（期末数） | AA1: 5601-01-01-02合同履约成本-工程施工-合同成本-直接材料费（期末数） | AB1: 5601-01-01-04合同履约成本-工程施工-合同成本-劳务成本（期末数） | AC1: 5601-01-01-05合同履约成本-工程施工-合同成本-专业分包成本（期末数） | AD1: 5601-01-01-06合同履约成本-工程施工-合同成本-其他直接费用（期末数） | AE1: 5601-01-01-07合同履约成本-工程施工-合同成本-间接费用转入（期末数） | AF1: 5601-01-01-01合同履约成本-工程施工-合同成本-直接人工费（当年借方发生数） | AG1: 5601-01-01-02合同履约成本-工程施工-合同成本-直接材料费（当年借方发生数） | AH1: 5601-01-01-04合同履约成本-工程施工-合同成本-劳务成本（当年借方发生数） | AI1: 5601-01-01-05合同履约成本-工程施工-合同成本-专业分包成本（当年借方发生数） | AJ1: 5601-01-01-06合同履约成本-工程施工-合同成本-其他直接费用（当年借方发生数） | AK1: 5601-01-01-07合同履约成本-工程施工-合同成本-间接费用转入（当年借方发生数） | AL1: 5601-02合同履约成本-劳务成本（当年借方发生数） | AM1: 5801-01合同结算-收入结转 | AN1: 5801-02合同结算-价款结算 | AO1: 6001主营业务收入（当年贷方发生数） | AP1: 6401主营业务成本（当年借方发生数）
A2: 2022年东部环线枢纽铁路红线内公网覆盖项目设计施工总包联合 | B2: 4673398 | N2: 6473652.8 | P2: 45988566 | Q2: -4110384 | AC2: 65003844 | AD2: 252289.31 | AE2: 157598.63 | AM2: 68690666 | AN2: 27465637
A3: 2022年西工区老旧小区改造提质EPC项目（四标段） | B3: -12000000 | P3: 1001834.9 | Q3: -1098165.1 | R3: 0 | AC3: 11835780 | AE3: 947 | AM3: 12201835
A4: 2022年西工区老旧小区改造提质项目（四标段)EPC工程总承包合同 | P4: -49541.28 | Q4: -49541.28
A5: 2023年中国电信贵州公司贵广高铁贵州段公网覆盖扩容改造工程设计施工服务总承包采购 | B5: 2532770.9 | P5: 64457.42 | Q5: -6576.15 | R5: 0 | AA5: 3143639.8 | AC5: 5969487.2 | AE5: 8412 | AM5: 6283670.7 | AN5: 12676352
A6: 2024年渝湘高铁（重庆东至黔江段）红线内公网覆盖项目设计施工总包联合采购 | B6: 0 | N6: 7766050 | P6: 17778790 | Q6: -1711824.5 | R6: 102507.72 | AC6: 16299128 | AD6: 356066.04 | AE6: 323349.7 | AM6: 16803225
A7: 318大桥及相关工程EPC | P7: 632463.83 | Q7: 0
A8: B208-B号项目(EPC工程总承包) | B8: 1422295.3 | N8: 678049.72 | Q8: 0 | R8: 0 | W8: 673130.77 | AC8: 20585039 | AE8: 347240.46 | AM8: 22165297 | AN8: 22165297
A9: B208-民航院-2022-001号项目(EPC工程总承包) | B9: 8405313 | N9: 8552520.3 | Q9: 0 | R9: 737304.37 | W9: 1425368.4 | AC9: 42063613 | AM9: 43589236 | AN9: 43589236
A10: B208-土建三院-2020-001号项目(EPC工程总承包) | B10: 74736.28 | N10: 1813597.9 | Q10: 0 | R10: 0.01 | AC10: 31521539 | AE10: 349428.56 | AM10: 33031780 | AN10: 33031780
A11: CRECG-民航院-2023-01 | B11: 12144687 | C11: 0 | L11: 3036171.7 | M11: 0 | N11: 10204150 | Q11: 0 | R11: 1253465.4 | AA11: 16005604 | AC11: 63622546 | AE11: 24306.67 | AM11: 82859221 | AN11: 92849287
A12: G331线青河至富蕴至阿勒泰段公路建设项目（EPC模式）（四标段） | B12: 21137831 | C12: 0 | L12: 21795131 | M12: 0 | N12: 23190681 | P12: -25000 | Q12: 0 | W12: 21206663 | AC12: 6.4852179e+08 | AE12: 718592.4 | AM12: 6.6651777e+08 | AN12: 6.6651777e+08
A13: G347无为市通江大道快速化改造工程及S330六芜路福渡段快速化改造工程 | B13: 1.598801e+08 | M13: 72771174 | N13: 1.3975362e+08 | Q13: 0 | R13: 26621722 | W13: 91774255 | AB13: 213961 | AC13: 8.9726651e+08 | AE13: 1696888 | AM13: 9.1984496e+08 | AN13: 9.1740234e+08
A14: S205利州区河西街道办事处（杨家岩）至下西街道办事处（（塔山湾）段改建工程（下穿广元铁路集装箱运输组货中心段）项目勘察设计施工一体化总承包（EPC） | B14: 16287624 | C14: 9681349 | M14: 2689146 | N14: 31202633 | P14: 0.69 | Q14: 0 | AC14: 97786543 | AE14: 132192.89 | AM14: 1.0081087e+08 | AN14: 1.0081087e+08
A15: S205利州区河西街道办事处（杨家岩）至下西街道办事处（塔山湾）段改建工程（下穿广元铁路集装箱运输组货中心段）勘察设计施工一体化总承包（EPC） | Q15: 0 | AE15: 3720.13
A16: 安宁工业园区大宗工业物资公铁联运物流园项目涉铁部分（铁路专用线部分）工程设计施工总承包 | B16: 16829786 | N16: 6010934 | P16: 55523276 | Q16: -4476723.5 | R16: 9917541.7 | AC16: 1.6156044e+08 | AM16: 1.7278988e+08 | AN16: 1.7278988e+08
A17: 成达万高铁遂宁市范围内三电及管线迁改EPC | B17: 72516056 | C17: 0 | M17: 6761405.2 | N17: 68925268 | Q17: 0 | R17: 6545845.4 | W17: 5224809.8 | AB17: 431625.33 | AC17: 1.9436455e+08 | AE17: 512269.54 | AM17: 2.046089e+08 | AN17: 2.067708e+08
A18: 成达万铁路资阳段三电及地下、地面管线迁改项目 | B18: 13549888 | C18: 3086596 | M18: 5511504.3 | N18: 14293337 | P18: 1730189.8 | Q18: 0 | R18: 2806051.3 | W18: 2727481.8 | AC18: 1.6270463e+08 | AE18: 2551.09 | AM18: 1.6795316e+08 | AN18: 1.6854753e+08
A19: 成都市双流区滨河路下穿成昆铁路立交工程项目EPC总承包合同 | B19: 7506154.8 | N19: 6878062.4 | Q19: 0 | R19: 619774.26 | Z19: 36841.47 | AB19: 98965.77 | AC19: 21033830 | AE19: 79970.76 | AM19: 22862859 | AN19: 22890382
A20: 成都天府国际机场PRT项目部 | C20: -85077 | N20: 4880868 | Q20: 0 | R20: 188200.15 | Z20: 48143.39 | AA20: 76639160 | AB20: 133104.12 | AC20: 427064.22 | AE20: 1789703.6
A21: 成昆复线冕宁站站前广场项目等6个项目集（EPC） | B21: 77093170 | N21: 76962832 | Q21: 0 | R21: 6472471.9 | AC21: 2.4951234e+08 | AE21: 101742.2 | AM21: 2.5630773e+08 | AN21: 2.5127124e+08
A22: 成绵乐高铁峨九路立交道岔特大桥桥梁景观工程及峨九路下穿坡道侧壁改造工程EPC | P22: 173000 | Q22: 0
A23: 成渝铁路重庆站至江津站段改造工程高等级管线迁改 | B23: 14921.55 | M23: 301963.2 | N23: 2292256.9 | P23: 12984546 | Q23: -1168609.1 | R23: 39854.28 | AC23: 15603193 | AE23: 64081.73 | AM23: 16959992 | AN23: 9993497.1
A24: 成渝中线高铁成都段三电及管线迁改工程总包项目 | B24: 10018101 | C24: 5830345.8 | M24: 5388191.4 | N24: 38933198 | P24: 6202495.6 | Q24: 0 | R24: 2965811.8 | W24: 5286576.7 | AB24: 72028.46 | AC24: 1.6166901e+08 | AE24: 260883.77 | AM24: 1.6701959e+08 | AN24: 1.6476732e+08
A25: 成渝中线铁路（含十陵南站）资阳段三电及管线迁改总包 | B25: 92191183 | M25: 6827228.3 | N25: 91247709 | P25: 2307470.2 | Q25: 0 | R25: 8340969.8 | W25: 6613877.5 | AC25: 2.0225925e+08 | AE25: 33663.37 | AM25: 2.0851469e+08 | AN25: 2.0878374e+08
A26: 城东区养老示范基地市政管线下穿国家粮食和物资储备局青海局535处铁路专用防护涵工程（设计、采购、施工）EPC项目（待院签） | B26: 0 | N26: 1906920.1 | Q26: 0 | R26: 0 | AC26: 1749468 | AM26: 7889709.2 | AN26: 7413873.3
A27: 城口县东部新区配套基础设施建设项目（一期）巴山大道、冲沟治理工程和城口高铁站前广场及配套设施项目打捆EPC总承包 | B27: 1500050 | Q27: 0 | R27: 0 | AB27: 749724.96 | AE27: 1447976.2 | AL27: 1607594.7
A28: 齿轨列车试验线建设项目工程总承包 | M28: 829800 | N28: 710350.17 | Q28: 0 | AA28: 7676281.2 | AC28: 12990826 | AE28: 51663.07 | AM28: 12990826 | AN28: 12990826
A29: 川藏铁路天府站至朝阳湖“三电”迁改项目总承包EPC | B29: 21292704 | C29: 4647254.5 | M29: 3722241.8 | N29: 24508888 | P29: 4943887.8 | Q29: 0 | R29: 2048940.5 | W29: 3498907.3 | AB29: 187340.48 | AC29: 1.0700022e+08 | AE29: 359462.23 | AM29: 1.1035597e+08 | AN29: 1.1383003e+08
A30: 川南城际铁路临港高铁站片区基础设施项目-嘉信路立交工程勘察设计施工 | B30: 14453830 | N30: 13174417 | Q30: 0 | R30: 1193435.5 | AC30: 62913777 | AE30: 15948.11 | AM30: 65535184 | AN30: 66205349
A31: 达州城区智能交通系统项目 | Q31: 0 | AC31: 1019912.6
A32: 达州市中心城区道路交通安全设施运维服务 | Q32: 0 | AA32: 2247656.8 | AC32: 4874066.7 | AL32: 2661941.5
A33: 大理州集中建园贝特瑞片区工程设施建设项目（第1标段：三通一平工程）建设项目 | B33: 1.4112537e+08 | M33: 13699259 | N33: 1.2438244e+08 | P33: 14000000 | Q33: 0 | R33: 11627722 | W33: 13397201 | AC33: 4.0970033e+08 | AD33: 461037.73 | AE33: 1254355.9 | AM33: 4.1876663e+08 | AN33: 4.189376e+08
A34: 大理州集中建园材料新能源产业片区基础设施建设项目（一期）工程总承包合同 | B34: 92386595 | L34: 8675790.6 | M34: 0 | N34: 89233758 | Q34: 0 | R34: 10408821 | W34: 8420850 | AC34: 2.5751835e+08 | AD34: 331226.41 | AE34: 496905.66 | AM34: 2.6412138e+08 | AN34: 2.653147e+08
A35: 大丽铁路公网通信覆盖工程EPC项目 | Q35: 0 | AA35: 300540.92 | AC35: 56708370 | AE35: 114984.04 | AM35: 26821503 | AN35: 26912467
A36: 大沙坝油库铁路专用线扩能改造项目EPC | P36: 6728807.3 | Q36: -951192.66 | AE36: 23466.88
A37: 岱阳大街下穿京沪铁路立交桥改建工程总承包（EPC） | C37: 25000000 | P37: 67156679 | Q37: 0 | AE37: 2516817.5
A38: 钒钛高新区物流园主干道北延线 | B38: 15101120 | L38: 1107107 | M38: 0 | N38: 14194506 | Q38: 0 | R38: 956716.21 | W38: 1667660.1 | AC38: 49775459 | AE38: 97288.35 | AM38: 51580787 | AN38: 51580787
A39: 防东高铁（红线内）公网覆盖工程设计施工总承包项目 | B39: 398813.95 | Q39: 0 | R39: 32929.59 | AA39: 880927.72 | AC39: 1396515.1 | AE39: 5078.57 | AM39: 1464828.5 | AN39: 1829421.8
A40: 非生产性工业用房及附属设施（中铁轨道交通高科技产业园1号地块）三期设计-施工总承包II标段 | B40: 5618759.5 | L40: 1195419.1 | M40: 0 | N40: 9496125.3 | Q40: 0 | R40: 176449.82 | W40: 1322316.2 | AB40: 483940.05 | AC40: 40437805 | AE40: 69299.03 | AM40: 43248989 | AN40: 36556993
...

Sheet 武隆污水（不上系统）
A1: 表一：基础信息表
A2: 单位名称 | B2: 合同名称 | C2: 合同编号 | D2: 合同类型 | E2: 合同金额 | K2: 管理费比例 | L2: 共享系统部门名称 | M2: 共享系统项目名称 | N2: 合同签订单位 | O2: 项目管理单位 | P2: 业主财务联系人及电话 | Q2: 分包方财务联系人及电话 | R2: 项目部经理及电话 | S2: 合同开工日期 | T2: 预计竣工时间 | U2: 合同工期 | V2: 工程类型 | W2: 项目所在地（*省*市） | X2: 项目状态 | Y2: 工程进度款支付比例 | Z2: 勘察设计费支付比例 | AA2: 主管税务机构名称 | AB2: 税务管理员及电话 | AC2: 银行行号 | AD2: 开户行 | AE2: 银行行号 | AF2: 银行账户名称 | AG2: 银行账号 | AH2: 银行地址 | AI2: 银行联系人 | AJ2: 备注
E3: 勘察设计 | F3: 工程施工 | G3: 设备采购 | H3: 业主承担管理费 | I3: 技术服务等 | J3: 合计
A4: 重庆碧水源建设项目管理有限责任公司 | B4: 武隆污水处理厂二期扩建工程EPC（设计、施工、采购、调试、试运行等交钥匙工程）总承包合同 | C4: 2017-生环院(总包)-001 | D4: 总包合同 | E4: 2933770.4 | F4: 1.16656e+08 | J4: =SUM(E4:I4) -> 1.1958977e+08 | K4: =(F4-F5-F6)/F4 -> 0.027878598 | L4: 中铁二院武隆污水厂项目部 | M4: 武隆污水处理厂二期扩建工程EPC | N4: 经计部 | O4: 生态环境院 | V4: 市政 | W4: 重庆市武隆区 | X4: 竣工未决算 | Y4: 1 | Z4: 1
A5: 重庆对外建设（集团）有限公司 | B5: 武隆污水处理厂二.期扩建工程EPC总承包联合体协议书 | C5: 2017-生环院(总包)-001 | D5: 分包合同 | F5: 1.134038e+08 | J5: =SUM(E5:I5) -> 1.134038e+08
A6: 重庆两江交通规划勘察设计研究院有限公司 | B6: 技术服务合同书 | D6: 分包合同 | E6: 2000000 | J6: =SUM(E6:I6) -> 2000000
A7: 四川德维工程管理咨询有限公司 | B7: 工程造价咨询合同 | D7: 分包合同 | E7: 200000 | J7: =E7 -> 200000
A8: 表二：汇总表
A9: 单位名称 | B9: 累计验工计价 | H9: 累计开票 | N9: 累计收入或成本 | T9: 累计收款/付款 | U9: 银行账户余额 | V9: 工程施工预计总收入 | W9: 工程施工预计总成本
B10: 勘察设计 | C10: 工程施工 | D10: 设备采购 | E10: 业主承担管理费 | F10: 服务费 | G10: 合计 | H10: 勘察设计 | I10: 工程施工 | J10: 设备采购 | K10: 业主承担管理费 | L10: 服务费 | M10: 合计 | N10: 勘察设计 | O10: 工程施工 | P10: 设备采购 | Q10: 业主承担管理费 | R10: 服务费 | S10: 合计
A11: 重庆碧水源建设项目管理有限责任公司 | B11: =SUMIFS($E$20:$E$46,$D$20:$D$46,$B$10,$A$20:$A$46,$A$11) -> 2933770.4 | C11: =SUMIFS($E$20:$E$46,$D$20:$D$46,C10,$A$20:$A$46,A11) -> 1.16656e+08 | D11: =SUMIFS($E$20:$E$46,$D$20:$D$46,D10,$A$20:$A$46,A11) -> 0 | E11: =SUMIFS($E$20:$E$46,$D$20:$D$46,E10,$A$20:$A$46,A11) -> 0 | F11: =SUMIFS($E$20:$E$46,$D$20:$D$46,F10,$A$20:$A$46,A11) -> 0 | G11: =SUM(B11:F11) -> 1.1958977e+08 | H11: =SUMIFS($V$20:$V$46,$R$20:$R$46,$H$10,$P$20:$P$46,$A$11) -> 2933770.4 | I11: =SUMIFS($V$20:$V$46,$R$20:$R$46,I10,$P$20:$P$46,$A$11) -> 1.16656e+08 | J11: =SUMIFS($V$20:$V$46,$R$20:$R$46,$J$10,$P$20:$P$46,$A$11) -> 0 | K11: =SUMIFS($V$20:$V$46,$R$20:$R$46,$K$10,$P$20:$P$46,$A$11) -> 0 | L11: =SUMIFS($V$20:$V$46,$R$20:$R$46,$L$10,$P$20:$P$46,$A$11) -> 0 | M11: =SUM(H11:L11) -> 1.1958977e+08 | N11: =SUMIFS($O$20:$O$45,$N$20:$N$45,N10,$L$20:$L$45,A11) -> 2767707.9 | O11: =SUMIFS($O$20:$O$45,$N$20:$N$45,O10,$L$20:$L$45,A11) -> 1.0622063e+08 | P11: =SUMIFS($O$20:$O$45,$N$20:$N$45,P10,$L$20:$L$45,A11) -> 0 | Q11: =SUMIFS($O$20:$O$45,$N$20:$N$45,Q10,$L$20:$L$45,A11) -> 0 | R11: =SUMIFS($O$20:$O$45,$N$20:$N$45,R10,$L$20:$L$45,A11) -> 0 | S11: =SUM(N11:R11) -> 1.0898834e+08 | T11: =SUMIF($Z$20:$Z$46,A11,$AE$20:$AE$46) -> 1.1958977e+08 | V11: =106220633.37 -> 1.0622063e+08 | W11: 1.0324322e+08
A12: 重庆对外建设（集团）有限公司 | B12: =SUMIFS($E$51:$E$76,$D$51:$D$76,B10,$A$51:$A$76,A12) -> 0 | C12: =SUMIFS($E$51:$E$76,$D$51:$D$76,C10,$A$51:$A$76,A12) -> 1.134038e+08 | D12: =SUMIFS($E$51:$E$76,$D$51:$D$76,D10,$A$51:$A$76,A12) -> 0 | E12: =SUMIFS($E$51:$E$76,$D$51:$D$76,E10,$A$51:$A$76,A12) -> 0 | F12: =SUMIFS($E$51:$E$76,$D$51:$D$76,F10,$A$51:$A$76,A12) -> 0 | G12: =SUM(B12:F12) -> 1.134038e+08 | H12: =SUMIFS($R$51:$R$76,$N$51:$N$76,H10,$L$51:$L$76,A12) -> 0 | I12: =SUMIFS($R$51:$R$76,$N$51:$N$76,I10,$L$51:$L$76,A12) -> 1.134038e+08 | J12: =SUMIFS($R$51:$R$76,$N$51:$N$76,J10,$L$51:$L$76,A12) -> 0 | K12: =SUMIFS($R$51:$R$76,$N$51:$N$76,K10,$L$51:$L$76,A12) -> 0 | L12: =SUMIFS($R$51:$R$76,$N$51:$N$76,L10,$L$51:$L$76,A12) -> 0 | M12: =SUM(H12:L12) -> 1.134038e+08 | N12: =SUMIFS($G$51:$G$76,$D$51:$D$76,N10,$A$51:$A$76,A12) -> 0 | O12: =SUMIFS($G$51:$G$76,$D$51:$D$76,$O$10,$A$51:$A$76,A12) -> 1.0324322e+08 | P12: =SUMIFS($G$51:$G$76,$D$51:$D$76,$P$10,$A$51:$A$76,A12) -> 0 | Q12: =SUMIFS($G$51:$G$76,$D$51:$D$76,$Q$10,$A$51:$A$76,A12) -> 0 | R12: =SUMIFS($G$51:$G$76,$D$51:$D$76,$R$10,$A$51:$A$76,A12) -> 0 | S12: =SUM(N12:R12) -> 1.0324322e+08 | T12: =SUMIF($V$51:$V$75,A12,$AA$51:$AA$76) -> 1.134038e+08
A13: 重庆两江交通规划勘察设计研究院有限公司 | B13: =SUMIFS($E$51:$E$76,$D$51:$D$76,B10,$A$51:$A$76,A13) -> 1550000 | C13: =SUMIFS($E$51:$E$76,$D$51:$D$76,C10,$A$51:$A$76,A13) -> 0 | D13: =SUMIFS($E$51:$E$76,$D$51:$D$76,D10,$A$51:$A$76,A13) -> 0 | E13: =SUMIFS($E$51:$E$76,$D$51:$D$76,E10,$A$51:$A$76,A13) -> 0 | F13: =SUMIFS($E$51:$E$76,$D$51:$D$76,F10,$A$51:$A$76,A13) -> 0 | G13: =SUM(B13:F13) -> 1550000 | H13: =SUMIFS($R$51:$R$76,$N$51:$N$76,H10,$L$51:$L$76,A13) -> 1550000 | I13: =SUMIFS($R$51:$R$76,$N$51:$N$76,I10,$L$51:$L$76,A13) -> 0 | J13: =SUMIFS($R$51:$R$76,$N$51:$N$76,J10,$L$51:$L$76,A13) -> 0 | K13: =SUMIFS($R$51:$R$76,$N$51:$N$76,K10,$L$51:$L$76,A13) -> 0 | L13: =SUMIFS($R$51:$R$76,$N$51:$N$76,L10,$L$51:$L$76,A13) -> 0 | M13: =SUM(H13:L13) -> 1550000 | N13: =SUMIFS($G$51:$G$76,$D$51:$D$76,$N$10,$A$51:$A$76,A13) -> 1462264.2 | O13: =SUMIFS($G$51:$G$76,$D$51:$D$76,$O$10,$A$51:$A$76,A13) -> 0 | P13: =SUMIFS($G$51:$G$76,$D$51:$D$76,$P$10,$A$51:$A$76,A13) -> 0 | Q13: =SUMIFS($G$51:$G$76,$D$51:$D$76,$Q$10,$A$51:$A$76,A13) -> 0 | R13: =SUMIFS($G$51:$G$76,$D$51:$D$76,$R$10,$A$51:$A$76,A13) -> 0 | S13: =SUM(N13:R13) -> 1462264.2 | T13: =SUMIF($V$51:$V$75,A13,$AA$51:$AA$76) -> 1550000
A14: 四川德维工程管理咨询有限公司 | B14: =SUMIFS($E$51:$E$76,$D$51:$D$76,B11,$A$51:$A$76,A14) -> 0 | C14: =SUMIFS($E$51:$E$76,$D$51:$D$76,C11,$A$51:$A$76,A14) -> 0 | D14: =SUMIFS($E$51:$E$76,$D$51:$D$76,D11,$A$51:$A$76,A14) -> 0 | E14: =SUMIFS($E$51:$E$76,$D$51:$D$76,E11,$A$51:$A$76,A14) -> 0 | F14: =SUMIFS($E$51:$E$76,$D$51:$D$76,F11,$A$51:$A$76,A14) -> 0 | G14: =SUM(B14:F14) -> 0 | H14: =SUMIFS($R$51:$R$76,$N$51:$N$76,H10,$L$51:$L$76,A14) -> 0 | I14: =SUMIFS($R$51:$R$76,$N$51:$N$76,I10,$L$51:$L$76,A14) -> 200000 | J14: =SUMIFS($R$51:$R$76,$N$51:$N$76,J11,$L$51:$L$76,A14) -> 0 | K14: =SUMIFS($R$51:$R$76,$N$51:$N$76,K11,$L$51:$L$76,A14) -> 0 | L14: =SUMIFS($R$51:$R$76,$N$51:$N$76,L11,$L$51:$L$76,A14) -> 0 | M14: =SUM(H14:L14) -> 200000 | N14: =SUMIFS($G$51:$G$76,$D$51:$D$76,$N$10,$A$51:$A$76,A14) -> 188679.25 | O14: =SUMIFS($G$51:$G$76,$D$51:$D$76,$O$10,$A$51:$A$76,A14) -> 0 | P14: =SUMIFS($G$51:$G$76,$D$51:$D$76,$P$10,$A$51:$A$76,A14) -> 0 | Q14: =SUMIFS($G$51:$G$76,$D$51:$D$76,$Q$10,$A$51:$A$76,A14) -> 0 | R14: =SUMIFS($G$51:$G$76,$D$51:$D$76,$R$10,$A$51:$A$76,A14) -> 0 | S14: =SUM(N14:R14) -> 188679.25 | T14: =SUMIF($V$51:$V$76,A14,$AA$51:$AA$76) -> 200000
G15: =G12+G13-C48 -> -200000 | M15: =M12+M13-R48 -> -200000 | S15: =S12+S13-G48 -> -188679.25 | T15: =T12+T13-AA48 -> -200000
A17: 表三：业主基础明细表 | C17: =SUM(C20:C44) -> 1.1958977e+08 | E17: =SUM(E20:E45) -> 1.1958977e+08 | G17: =SUM(G20:G45) -> 1.0898834e+08 | H17: =SUM(H20:H45) -> 10601433 | O17: =SUM(O20:O45) -> 1.0898834e+08 | V17: =SUM(V20:V45) -> 1.1958977e+08 | W17: =SUM(W20:W45) -> 1.0898834e+08 | X17: =SUM(X20:X45) -> 10601433 | AE17: =SUM(AE20:AE45) -> 1.1958977e+08
A18: 业主结算明细 | L18: 收入确认表 | P18: 开票明细表（可按开票时间汇总登记） | Z18: 收款明细
A19: 业主名称 | B19: 验工时间 | C19: 验工计价 | D19: 结算内容 | E19: 列账金额 | F19: 税率 | G19: 不含税金额(注意与账上保持一致） | H19: 税额(注意与账上保持一致） | I19: 列账凭证时间 | J19: 预付款转回 | K19: 罚没等其他金额 | L19: 业主名称 | M19: 凭证时间 | N19: 收入类型 | O19: 确认金额 | P19: 业主名称 | Q19: 凭证时间 | R19: 开票内容 | S19: 开票时间 | T19: 发票号码 | U19: 发票代码 | V19: 发票金额 | W19: 不含税金额 | X19: 税额 | Y19: 税率 | Z19: 单位名称 | AA19: 凭证日期 | AB19: 收款账户类型 | AC19: 收款账户名称 | AD19: 收款账户银行账号 | AE19: 收款金额 | AF19: 收款性质 | AG19: 收款备注
A20: 重庆碧水源建设项目管理有限责任公司 | C20: 11090000 | D20: 工程施工 | E20: 11090000 | F20: 0.11 | G20: =ROUND(E20/(1+F20),2) -> 9990991 | H20: =C20-G20 -> 1099009 | I20: 43089 | L20: 重庆碧水源建设项目管理有限责任公司 | M20: 43089 | N20: 工程施工 | O20: 9990991 | P20: 重庆碧水源建设项目管理有限责任公司 | Q20: 43089 | R20: 工程施工 | V20: 11090000 | W20: =ROUND(V20/(1+Y20),2) -> 9990991 | X20: =V20-W20 -> 1099009 | Y20: 0.11 | Z20: 重庆碧水源建设项目管理有限责任公司 | AA20: 44742 | AB20: 专户 | AC20: 中铁二院武隆污水厂项目部 | AE20: 1.16656e+08
A21: 重庆碧水源建设项目管理有限责任公司 | C21: 1500000 | D21: 工程施工 | E21: 1500000 | F21: 0.11 | G21: =ROUND(E21/(1+F21),2) -> 1351351.4 | H21: =C21-G21 -> 148648.65 | I21: 43089 | L21: 重庆碧水源建设项目管理有限责任公司 | M21: 43089 | N21: 工程施工 | O21: 1351351.4 | P21: 重庆碧水源建设项目管理有限责任公司 | Q21: 43089 | R21: 工程施工 | V21: 1500000 | W21: =ROUND(V21/(1+Y21),2) -> 1351351.4 | X21: =V21-W21 -> 148648.65 | Y21: 0.11 | Z21: 重庆碧水源建设项目管理有限责任公司 | AA21: 44742 | AB21: 专户 | AC21: 中铁二院武隆污水厂项目部 | AE21: 1911951.6
A22: 重庆碧水源建设项目管理有限责任公司 | C22: 19240000 | D22: 工程施工 | E22: 19240000 | F22: 0.11 | G22: =ROUND(E22/(1+F22),2) -> 17333333 | H22: =C22-G22 -> 1906666.7 | I22: 43139 | L22: 重庆碧水源建设项目管理有限责任公司 | M22: 43139 | N22: 工程施工 | O22: 17333333 | P22: 重庆碧水源建设项目管理有限责任公司 | Q22: 43139 | R22: 工程施工 | V22: 19240000 | W22: =ROUND(V22/(1+Y22),2) -> 17333333 | X22: =V22-W22 -> 1906666.7 | Y22: 0.11 | Z22: 重庆碧水源建设项目管理有限责任公司 | AA22: 44742 | AB22: 专户 | AC22: 中铁二院武隆污水厂项目部 | AE22: 1021818.2
A23: 重庆碧水源建设项目管理有限责任公司 | C23: 1950000 | D23: 勘察设计 | E23: 1950000 | F23: 0.06 | G23: =ROUND(E23/(1+F23),2) -> 1839622.6 | H23: =C23-G23 -> 110377.36 | I23: 43139 | L23: 重庆碧水源建设项目管理有限责任公司 | M23: 43139 | N23: 勘察设计 | O23: 1839622.6 | P23: 重庆碧水源建设项目管理有限责任公司 | Q23: 43139 | R23: 勘察设计 | V23: 1950000 | W23: =ROUND(V23/(1+Y23),2) -> 1839622.6 | X23: =V23-W23 -> 110377.36 | Y23: 0.06
A24: 重庆碧水源建设项目管理有限责任公司 | C24: 13500000 | D24: 工程施工 | E24: 13500000 | F24: 0.1 | G24: =ROUND(E24/(1+F24),2) -> 12272727 | H24: =C24-G24 -> 1227272.7 | I24: 43300 | L24: 重庆碧水源建设项目管理有限责任公司 | M24: 43300 | N24: 工程施工 | O24: 12272727 | P24: 重庆碧水源建设项目管理有限责任公司 | Q24: 43300 | R24: 工程施工 | V24: 13500000 | W24: =ROUND(V24/(1+Y24),2) -> 12272727 | X24: =V24-W24 -> 1227272.7 | Y24: 0.1
A25: 重庆碧水源建设项目管理有限责任公司 | C25: 7500000 | D25: 工程施工 | E25: 7500000 | F25: 0.1 | G25: =ROUND(E25/(1+F25),2) -> 6818181.8 | H25: =C25-G25 -> 681818.18 | I25: 43395 | L25: 重庆碧水源建设项目管理有限责任公司 | M25: 43395 | N25: 工程施工 | O25: 6818181.8 | P25: 重庆碧水源建设项目管理有限责任公司 | Q25: 43395 | R25: 工程施工 | V25: 7500000 | W25: =ROUND(V25/(1+Y25),2) -> 6818181.8 | X25: =V25-W25 -> 681818.18 | Y25: 0.1
A26: 重庆碧水源建设项目管理有限责任公司 | C26: 6000000 | D26: 工程施工 | E26: 6000000 | F26: 0.1 | G26: =ROUND(E26/(1+F26),2) -> 5454545.5 | H26: =C26-G26 -> 545454.55 | I26: 43444 | L26: 重庆碧水源建设项目管理有限责任公司 | M26: 43444 | N26: 工程施工 | O26: 5454545.5 | P26: 重庆碧水源建设项目管理有限责任公司 | Q26: 43444 | R26: 工程施工 | V26: 6000000 | W26: =ROUND(V26/(1+Y26),2) -> 5454545.5 | X26: =V26-W26 -> 545454.55 | Y26: 0.1
A27: 重庆碧水源建设项目管理有限责任公司 | C27: 325000 | D27: 勘察设计 | E27: 325000 | F27: 0.06 | G27: =ROUND(E27/(1+F27),2) -> 306603.77 | H27: =C27-G27 -> 18396.23 | I27: 43486 | L27: 重庆碧水源建设项目管理有限责任公司 | M27: 43486 | N27: 勘察设计 | O27: 306603.77 | P27: 重庆碧水源建设项目管理有限责任公司 | Q27: 43486 | R27: 勘察设计 | V27: 325000 | W27: =ROUND(V27/(1+Y27),2) -> 306603.77 | X27: =V27-W27 -> 18396.23 | Y27: 0.06
A28: 重庆碧水源建设项目管理有限责任公司 | C28: 6000000 | D28: 工程施工 | E28: 6000000 | F28: 0.1 | G28: =ROUND(E28/(1+F28),2) -> 5454545.5 | H28: =C28-G28 -> 545454.55 | I28: 43488 | L28: 重庆碧水源建设项目管理有限责任公司 | M28: 43488 | N28: 工程施工 | O28: 5454545.5 | P28: 重庆碧水源建设项目管理有限责任公司 | Q28: 43488 | R28: 工程施工 | V28: 6000000 | W28: =ROUND(V28/(1+Y28),2) -> 5454545.5 | X28: =V28-W28 -> 545454.55 | Y28: 0.1
A29: 重庆碧水源建设项目管理有限责任公司 | C29: 220000 | D29: 工程施工 | E29: 220000 | F29: 0.1 | G29: =ROUND(E29/(1+F29),2) -> 200000 | H29: =C29-G29 -> 20000 | I29: 43522 | L29: 重庆碧水源建设项目管理有限责任公司 | M29: 43522 | N29: 工程施工 | O29: 200000 | P29: 重庆碧水源建设项目管理有限责任公司 | Q29: 43522 | R29: 工程施工 | V29: 220000 | W29: =ROUND(V29/(1+Y29),2) -> 200000 | X29: =V29-W29 -> 20000 | Y29: 0.1
A30: 重庆碧水源建设项目管理有限责任公司 | C30: 7940000 | D30: 工程施工 | E30: 7940000 | F30: 0.09 | G30: =ROUND(E30/(1+F30),2) -> 7284403.7 | H30: =C30-G30 -> 655596.33 | I30: 43619 | L30: 重庆碧水源建设项目管理有限责任公司 | M30: 43619 | N30: 工程施工 | O30: 7284403.7 | P30: 重庆碧水源建设项目管理有限责任公司 | Q30: 43619 | R30: 工程施工 | V30: 7940000 | W30: =ROUND(V30/(1+Y30),2) -> 7284403.7 | X30: =V30-W30 -> 655596.33 | Y30: 0.09
A31: 重庆碧水源建设项目管理有限责任公司 | C31: 2790560 | D31: 工程施工 | E31: 2790560 | F31: 0.09 | G31: =ROUND(E31/(1+F31),2) -> 2560146.8 | H31: =C31-G31 -> 230413.21 | I31: 43647 | L31: 重庆碧水源建设项目管理有限责任公司 | M31: 43647 | N31: 工程施工 | O31: 2560146.8 | P31: 重庆碧水源建设项目管理有限责任公司 | Q31: 43647 | R31: 工程施工 | V31: 2790560 | W31: =ROUND(V31/(1+Y31),2) -> 2560146.8 | X31: =V31-W31 -> 230413.21 | Y31: 0.09
A32: 重庆碧水源建设项目管理有限责任公司 | C32: 9720000 | D32: 工程施工 | E32: 9720000 | F32: 0.09 | G32: =ROUND(E32/(1+F32),2) -> 8917431.2 | H32: =C32-G32 -> 802568.81 | I32: 43738 | L32: 重庆碧水源建设项目管理有限责任公司 | M32: 43738 | N32: 工程施工 | O32: 8917431.2 | P32: 重庆碧水源建设项目管理有限责任公司 | Q32: 43738 | R32: 工程施工 | V32: 9720000 | W32: =ROUND(V32/(1+Y32),2) -> 8917431.2 | X32: =V32-W32 -> 802568.81 | Y32: 0.09
A33: 重庆碧水源建设项目管理有限责任公司 | C33: 697640 | D33: 工程施工 | E33: 697640 | F33: 0.09 | G33: =ROUND(E33/(1+F33),2) -> 640036.7 | H33: =C33-G33 -> 57603.3 | I33: 43796 | L33: 重庆碧水源建设项目管理有限责任公司 | M33: 43796 | N33: 工程施工 | O33: 640036.7 | P33: 重庆碧水源建设项目管理有限责任公司 | Q33: 43796 | R33: 工程施工 | V33: 697640 | W33: =ROUND(V33/(1+Y33),2) -> 640036.7 | X33: =V33-W33 -> 57603.3 | Y33: 0.09
A34: 重庆碧水源建设项目管理有限责任公司 | C34: 3420000 | D34: 工程施工 | E34: 3420000 | F34: 0.09 | G34: =ROUND(E34/(1+F34),2) -> 3137614.7 | H34: =C34-G34 -> 282385.32 | I34: 43921 | L34: 重庆碧水源建设项目管理有限责任公司 | M34: 43921 | N34: 工程施工 | O34: 3137614.7 | P34: 重庆碧水源建设项目管理有限责任公司 | Q34: 43921 | R34: 工程施工 | V34: 3420000 | W34: =ROUND(V34/(1+Y34),2) -> 3137614.7 | X34: =V34-W34 -> 282385.32 | Y34: 0.09
... A40: 重庆碧水源建设项目管理有限责任公司 | C40: 10142759 | D40: 工程施工 | E40: 10142759 | F40: 0.09 | G40: =ROUND(E40/(1+F40),2) -> 9305283.1 | H40: =C40-G40 -> 837475.48 | I40: 45190 | L40: 重庆碧水源建设项目管理有限责任公司 | M40: 44561 | N40: 工程施工 | O40: -2709143.8 | P40: 重庆碧水源建设项目管理有限责任公司 | Q40: 44798 | R40: 勘察设计 | V40: 549054.08 | W40: =ROUND(V40/(1+Y40),2) -> 517975.55 | X40: =V40-W40 -> 31078.53 | Y40: 0.06
L41: 重庆碧水源建设项目管理有限责任公司 | M41: 44561 | N41: 勘察设计 | O41: 103505.95
L42: 重庆碧水源建设项目管理有限责任公司 | M42: 44798 | N42: 勘察设计 | O42: 517975.55
L43: 重庆碧水源建设项目管理有限责任公司 | M43: 44926 | N43: 工程施工 | O43: 8528024.7
A48: 表四：分包方基础明细表 | C48: =SUM(C51:C75) -> 1.151538e+08 | E48: =SUM(E51:E75) -> 1.151538e+08 | G48: =SUM(G51:G75) -> 1.0489416e+08 | H48: =SUM(H51:H75) -> 10259639 | J48: =SUM(J51:J75) -> 0 | K48: =SUM(K51:K75) -> 0 | R48: =SUM(R51:R75) -> 1.151538e+08 | S48: =SUM(S51:S75) -> 1.0489416e+08 | T48: =SUM(T51:T75) -> 10259639 | AA48: =SUM(AA51:AA75) -> 1.151538e+08
A49: 分包（采购）结算明细表 | L49: 分包（采购）发票明细表开票明细表（可按开票时间汇总登记） | V49: 分包（采购）付款明细表
A50: 单位名称 | B50: 验工时间 | C50: 验工计价 | D50: 结算内容 | E50: 金额 | F50: 税率 | G50: 不含税金额(注意与账上保持一致） | H50: 税额(注意与账上保持一致） | I50: 列账凭证时间 | J50: 预付款转回 | K50: 罚没等其他金额 | L50: 单位名称 | M50: 凭证时间 | N50: 开票内容 | O50: 开票时间 | P50: 发票号码 | Q50: 发票代码 | R50: 发票金额 | S50: 不含税金额 | T50: 税额 | U50: 税率 | V50: 单位名称 | W50: 凭证日期 | X50: 付款账户类型 | Y50: 付款账户名称 | Z50: 付款账户银行账号 | AA50: 付款金额 | AB50: 付款性质 | AC50: 付款备注
...

Sheet 攀枝花大渡口
A1: 表一：基础信息表
A2: 单位名称 | B2: 合同名称 | C2: 合同编号 | D2: 合同类型 | E2: 合同金额 | K2: 管理费比例 | L2: 共享系统部门名称 | M2: 共享系统项目名称 | N2: 合同签订单位 | O2: 项目管理单位 | P2: 业主财务联系人及电话 | Q2: 分包方财务联系人及电话 | R2: 项目部经理及电话 | S2: 合同开工日期 | T2: 预计竣工时间 | U2: 合同工期 | V2: 工程类型 | W2: 项目所在地（*省*市） | X2: 项目状态 | Y2: 工程进度款支付比例 | Z2: 勘察设计费支付比例 | AA2: 主管税务机构名称 | AB2: 税务管理员及电话 | AC2: 银行行号 | AD2: 开户行 | AE2: 银行行号 | AF2: 银行账户名称 | AG2: 银行账号 | AH2: 银行地址 | AI2: 银行联系人 | AJ2: 备注
E3: 勘察设计 | F3: 工程施工 | G3: 设备采购 | H3: 业主承担管理费 | I3: 技术服务等 | J3: 合计
A4: 攀枝花市水务（集团）有限公司 | B4: 攀枝花市大渡口污水处理厂提标升级改造工程项目勘察设计材料及设备采购施工总承包 | C4: 2019-生环院(总包)-001 | D4: 总包合同 | E4: 1520000 | F4: =26900000-G4-E4 -> 13053600 | G4: 12326400 | J4: =SUM(E4:I4) -> 26900000 | K4: =(F4-F5)/F4 -> 0.022 | L4: 中铁二院攀枝花市大渡口污水处理厂提标升级改造工程EPC项目部 | M4: 攀枝花市大渡口污水处理厂提标升级改造工程项目勘察设计材料及设备采购施工总承包 | N4: 经计部 | O4: 生态环境院 | V4: 市政 | W4: 四川省攀枝花市 | X4: 收尾 | Y4: 0.9 | Z4: 0.8
A5: 四川锐信路桥工程有限公司 | B5: 攀枝花市大渡口污水处理厂提标升级改造工程勘察设计-材料及设备采购-施工总承包项目联合体补充协议 | C5: 2019-生环院(分包)(总包)-004 | D5: 分包合同 | F5: =13053600*0.978 -> 12766421 | J5: =SUM(E5:I5) -> 12766421
A6: 冶金工业部华东勘察基础工程总公司成都分公司 | B6: 攀枝花市大渡口污水处理厂提标升级改造工程详勘 | C6: 2019-生环院(自揽外包)(总包)-009 | D6: 分包合同 | E6: 220000 | J6: =SUM(E6:I6) -> 220000
A7: 上海恒实环保能源（集团）有限公司 | B7: 攀枝花市大渡口污水处理厂提标升级改造工程设备采购及伴随服务合同 | C7: 2019-生环院(分包)(总包)-005 | D7: 分包合同 | G7: =12326400*0.978 -> 12055219 | J7: =SUM(E7:I7) -> 12055219
A9: 表二：汇总表
A10: 单位名称 | B10: 累计验工计价 | H10: 累计开票 | N10: 累计收入或成本 | T10: 累计收款/付款 | U10: 银行账户余额 | V10: 工程施工预计总收入 | W10: 工程施工预计总成本
B11: 勘察设计 | C11: 工程施工 | D11: 设备采购 | E11: 业主承担管理费 | F11: 服务费 | G11: 合计 | H11: 勘察设计 | I11: 工程施工 | J11: 设备采购 | K11: 业主承担管理费 | L11: 服务费 | M11: 合计 | N11: 勘察设计 | O11: 工程施工 | P11: 设备采购 | Q11: 业主承担管理费 | R11: 服务费 | S11: 合计
A12: 攀枝花市水务（集团）有限公司 | B12: =SUMIFS($E$21:$E$47,$D$21:$D$47,$B$11,$A$21:$A$47,$A$12) -> 1520000 | C12: =SUMIFS($E$21:$E$47,$D$21:$D$47,C11,$A$21:$A$47,A12) -> 8466630 | D12: =SUMIFS($E$21:$E$47,$D$21:$D$47,D11,$A$21:$A$47,A12) -> 11849105 | E12: =SUMIFS($E$21:$E$47,$D$21:$D$47,E11,$A$21:$A$47,A12) -> 0 | F12: =SUMIFS($E$21:$E$47,$D$21:$D$47,F11,$A$21:$A$47,A12) -> 0 | G12: =SUM(B12:F12) -> 21835735 | H12: =SUMIFS($V$21:$V$47,$R$21:$R$47,$H$11,$P$21:$P$47,$A$12) -> 1216000 | I12: =SUMIFS($V$21:$V$47,$R$21:$R$47,I11,$P$21:$P$47,$A$12) -> 8788345 | J12: =SUMIFS($V$21:$V$47,$R$21:$R$47,$J$11,$P$21:$P$47,$A$12) -> 11849105 | K12: =SUMIFS($V$21:$V$47,$R$21:$R$47,$K$11,$P$21:$P$47,$A$12) -> 0 | L12: =SUMIFS($V$21:$V$47,$R$21:$R$47,$L$11,$P$21:$P$47,$A$12) -> 0 | M12: =SUM(H12:L12) -> 21853450 | N12: =SUMIFS($O$21:$O$46,$N$21:$N$46,N11,$L$21:$L$46,A12) -> 1433932.3 | O12: =SUMIFS($O$21:$O$46,$N$21:$N$46,O11,$L$21:$L$46,A12) -> 10512226 | P12: =SUMIFS($O$21:$O$46,$N$21:$N$46,P11,$L$21:$L$46,A12) -> 10485934 | Q12: =SUMIFS($O$21:$O$46,$N$21:$N$46,Q11,$L$21:$L$46,A12) -> 0 | R12: =SUMIFS($O$21:$O$46,$N$21:$N$46,R11,$L$21:$L$46,A12) -> 0 | S12: =SUM(N12:R12) -> 22432092 | T12: =SUMIF($Z$21:$Z$47,A12,$AE$21:$AE$47) -> 21853450 | V12: =F4/1.09 -> 11975780 | W12: =(F5+F7)/1.09 -> 11712313 | X12: 11975780 | Y12: 11712313
A13: 四川锐信路桥工程有限公司 | B13: =SUMIFS($E$52:$E$77,$D$52:$D$77,B11,$A$52:$A$77,A13) -> 0 | C13: =SUMIFS($E$52:$E$77,$D$52:$D$77,C11,$A$52:$A$77,A13) -> 10060410 | D13: =SUMIFS($E$52:$E$77,$D$52:$D$77,D11,$A$52:$A$77,A13) -> 0 | E13: =SUMIFS($E$52:$E$77,$D$52:$D$77,E11,$A$52:$A$77,A13) -> 0 | F13: =SUMIFS($E$52:$E$77,$D$52:$D$77,F11,$A$52:$A$77,A13) -> 0 | G13: =SUM(B13:F13) -> 10060410 | H13: =SUMIFS($R$52:$R$77,$N$52:$N$77,H11,$L$52:$L$77,A13) -> 0 | I13: =SUMIFS($R$52:$R$77,$N$52:$N$77,I11,$L$52:$L$77,A13) -> 9744771.5 | J13: =SUMIFS($R$52:$R$77,$N$52:$N$77,J11,$L$52:$L$77,A13) -> 0 | K13: =SUMIFS($R$52:$R$77,$N$52:$N$77,K11,$L$52:$L$77,A13) -> 0 | L13: =SUMIFS($R$52:$R$77,$N$52:$N$77,L11,$L$52:$L$77,A13) -> 0 | M13: =SUM(H13:L13) -> 9744771.5 | N13: =SUMIFS($G$52:$G$77,$D$52:$D$77,N11,$A$52:$A$77,A13) -> 0 | O13: =SUMIFS($G$52:$G$77,$D$52:$D$77,$O$11,$A$52:$A$77,A13) -> 9229734.4 | P13: =SUMIFS($G$52:$G$77,$D$52:$D$77,$P$11,$A$52:$A$77,A13) -> 0 | Q13: =SUMIFS($G$52:$G$77,$D$52:$D$77,$Q$11,$A$52:$A$77,A13) -> 0 | R13: =SUMIFS($G$52:$G$77,$D$52:$D$77,$R$11,$A$52:$A$77,A13) -> 0 | S13: =SUM(N13:R13) -> 9229734.4 | T13: =SUMIF($V$52:$V$77,A13,$AA$52:$AA$77) -> 9744771.5
A14: 冶金工业部华东勘察基础工程总公司成都分公司 | B14: =SUMIFS($E$52:$E$77,$D$52:$D$77,B11,$A$52:$A$77,A14) -> 220000 | C14: =SUMIFS($E$52:$E$77,$D$52:$D$77,C11,$A$52:$A$77,A14) -> 0 | D14: =SUMIFS($E$52:$E$77,$D$52:$D$77,D11,$A$52:$A$77,A14) -> 0 | E14: =SUMIFS($E$52:$E$77,$D$52:$D$77,E11,$A$52:$A$77,A14) -> 0 | F14: =SUMIFS($E$52:$E$77,$D$52:$D$77,F11,$A$52:$A$77,A14) -> 0 | G14: =SUM(B14:F14) -> 220000 | H14: =SUMIFS($R$52:$R$77,$N$52:$N$77,H11,$L$52:$L$77,A14) -> 220000 | I14: =SUMIFS($R$52:$R$77,$N$52:$N$77,I11,$L$52:$L$77,A14) -> 0 | J14: =SUMIFS($R$52:$R$77,$N$52:$N$77,J11,$L$52:$L$77,A14) -> 0 | K14: =SUMIFS($R$52:$R$77,$N$52:$N$77,K11,$L$52:$L$77,A14) -> 0 | L14: =SUMIFS($R$52:$R$77,$N$52:$N$77,L11,$L$52:$L$77,A14) -> 0 | M14: =SUM(H14:L14) -> 220000 | N14: =SUMIFS($G$52:$G$77,$D$52:$D$77,$N$11,$A$52:$A$77,A14) -> 207547.16 | O14: =SUMIFS($G$52:$G$77,$D$52:$D$77,$O$11,$A$52:$A$77,A14) -> 0 | P14: =SUMIFS($G$52:$G$77,$D$52:$D$77,$P$11,$A$52:$A$77,A14) -> 0 | Q14: =SUMIFS($G$52:$G$77,$D$52:$D$77,$Q$11,$A$52:$A$77,A14) -> 0 | R14: =SUMIFS($G$52:$G$77,$D$52:$D$77,$R$11,$A$52:$A$77,A14) -> 0 | S14: =SUM(N14:R14) -> 207547.16 | T14: =SUMIF($V$52:$V$77,A14,$AA$52:$AA$77) -> 220000 | AG14: 21853450
A15: 上海恒实环保能源（集团）有限公司 | B15: =SUMIFS($E$52:$E$77,$D$52:$D$77,B12,$A$52:$A$77,A15) -> 0 | C15: =SUMIFS($E$52:$E$77,$D$52:$D$77,C12,$A$52:$A$77,A15) -> 0 | D15: =SUMIFS($E$52:$E$77,$D$52:$D$77,D11,$A$52:$A$77,A15) -> 10438655 | E15: =SUMIFS($E$52:$E$77,$D$52:$D$77,E12,$A$52:$A$77,A15) -> 0 | F15: =SUMIFS($E$52:$E$77,$D$52:$D$77,F12,$A$52:$A$77,A15) -> 0 | G15: =SUM(B15:F15) -> 10438655 | H15: =SUMIFS($R$52:$R$77,$N$52:$N$77,H11,$L$52:$L$77,A15) -> 0 | I15: =SUMIFS($R$52:$R$77,$N$52:$N$77,I12,$L$52:$L$77,A15) -> 0 | J15: =SUMIFS($R$52:$R$77,$N$52:$N$77,J11,$L$52:$L$77,A15) -> 10438655 | K15: =SUMIFS($R$52:$R$77,$N$52:$N$77,K12,$L$52:$L$77,A15) -> 0 | L15: =SUMIFS($R$52:$R$77,$N$52:$N$77,L12,$L$52:$L$77,A15) -> 0 | M15: =SUM(H15:L15) -> 10438655 | N15: =SUMIFS($G$52:$G$77,$D$52:$D$77,$N$11,$A$52:$A$77,A15) -> 0 | O15: =SUMIFS($G$52:$G$77,$D$52:$D$77,$O$11,$A$52:$A$77,A15) -> 0 | P15: =SUMIFS($G$52:$G$77,$D$52:$D$77,$P$11,$A$52:$A$77,A15) -> 9237748.1 | Q15: =SUMIFS($G$52:$G$77,$D$52:$D$77,$Q$11,$A$52:$A$77,A15) -> 0 | R15: =SUMIFS($G$52:$G$77,$D$52:$D$77,$R$11,$A$52:$A$77,A15) -> 0 | S15: =SUM(N15:R15) -> 9237748.1 | T15: =SUMIF($V$52:$V$77,A15,$AA$52:$AA$77) -> 10438655
G16: =G13+G14-C49 -> -10438655 | M16: =M13+M14-R49 -> -10438655 | S16: =S13+S14-G49 -> -9237748.1 | T16: =T13+T14-AA49 -> -10438655
